Workbook

Sheet THONG_TIN_CHUNG
A2: Dự án
A3: Mã dự án
A4: Ngày lập
A5: Ngày update
A6: Người lập
A7: Mô tả
A8: DANH SÁCH HẠNG MỤC
A9: Sản phẩm | B9: số lượng | C9: Đơn vị gia công | D9: mã THCP ĐỐI TƯỢNG trên misa
A10: HRM30A6001 | B10: 10 | C10: TNJ | D10: DX1TNJ0023
A11: HRS20A6003 | B11: 10 | C11: TNJ | D11: DX1TNJ0024
A12: DHRM38A6001 | B12: 10 | C12: TNJ | D12: DX1TNJ0031
A13: SRC18A7501_MC_FSM | B13: 20 | C13: TNJ | D13: DX1TNJ0033
A14: GRU30A05-OF-L | B14: 10 | C14: TNJ | D14: DX1TNJ0039
A15: GRU30A05-OF-R | B15: 10 | C15: TNJ | D15: DX1TNJ0040
A16: NH12ESP01-DC (DRAFT) | D16: DX1TNJ0037
A17: NH12ESP01 (DRAFT) | D17: DX1TNJ0038

Sheet HRM30A6001
A8: CÔNG TY TNHH THƯƠNG MẠI DỊCH VỤ TECHNOJET
D15: BẢNG ĐỊNH MỨC VẬT TƯ - NHÂN CÔNG
D16: SẢN XUẤT 1 BỘ HOSE REEL MULTI WRAP 3 INCH 60 FEETS
D17: MODEL: HRM30A6001
I62: Số phát hành: 01/HRM15/DMKT
I63: TP. Hồ Chí Minh, ngày 21 tháng 11 năm 2025.
A66: PHẦN 1: Phần Định mức Vật tư-Nguyên vật liệu sản xuất
A67: 1.1 DINH_MUC_VAT_TU_SAN_XUAT
A68: Tên cụm chị tiết | B68: Mã số chi tiết/ bản vẽ | C68: Số lượng cụm chi tiết | D68: Tên vật tư/NVL dùng để sx | E68: Mã kho | F68: Hình ảnh NVL | G68: Đơn vị theo thiết kế | H68: Số lượng theo thiết kế | I68: Đơn vị hệ thống | J68: Tỉ trọng chuyển đổi | K68: Số lượng sau chuyển đổi | L68: Ghi chú
A69: KHUNG NHÔM | C69: 1 | D69: Nhôm V 50x50x5mm, THÔ, KHÔNG XI | E69: =VLOOKUP(D69,'KHO TNJ'!$B$6:$C1071,2,FALSE) -> CX1NOA0065 | G69: mm | H69: 1235
D70: Nhôm hộp 50x50x5mm, THÔ | E70: =VLOOKUP(D70,'KHO TNJ'!$B$6:$C1071,2,FALSE) -> CX1NOA0109 | G70: mm | H70: 6048
D71: Nhôm hộp 25x50x4mm, THÔ | E71: =VLOOKUP(D71,'KHO TNJ'!$B$6:$C1071,2,FALSE) -> CX1NOA0110 | G71: mm | H71: 802
D72: Ống inox 304 bóng 42,7x2mm | E72: =VLOOKUP(D72,'KHO TNJ'!$B$6:$C1071,2,FALSE) -> CX1NOA0404 | G72: mm | H72: 994
D73: Cây ty inox 304 (Cây tròn đặc): Phi 12mm | E73: =VLOOKUP(D73,'KHO TNJ'!$B$6:$C1071,2,FALSE) -> CX1NOA0151 | G73: mm | H73: 1294
D74: Nhựa POM dạng thanh tròn đặc, màu trắng, DN40 | E74: =VLOOKUP(D74,'KHO TNJ'!$B$6:$C1071,2,FALSE) -> CX1NOA0149 | G74: mm | H74: 92
D75: Tán inox 304 M12 | E75: =VLOOKUP(D75,'KHO TNJ'!$B$6:$C1071,2,FALSE) -> CX1NOA0025 | G75: Cái | H75: 17
D76: Bulong Inox 304 M12x70 | E76: =VLOOKUP(D76,'KHO TNJ'!$B$6:$C1071,2,FALSE) -> CX1NOA0115 | G76: Cái | H76: 3
D77: Bulong Inox 304 M12x40 | E77: =VLOOKUP(D77,'KHO TNJ'!$B$6:$C1071,2,FALSE) -> CX1NOA0011 | G77: Cái | H77: 3
D78: Bulong inox 304 M12x80 | E78: =VLOOKUP(D78,'KHO TNJ'!$B$6:$C1071,2,FALSE) -> CX1NOA0431 | G78: Cái | H78: 3
D79: Bạc đạn (Vòng bi) CN 6001-DDU V3 RBI | E79: =VLOOKUP(D79,'KHO TNJ'!$B$6:$C1071,2,FALSE) -> CX1RBI0427 | G79: Cái | H79: 4
D80: Long đền inox 304 M12x26x1mm | E80: =VLOOKUP(D80,'KHO TNJ'!$B$6:$C1071,2,FALSE) -> CX1NOA0277 | G80: Cái | H80: 34
D81: PAT GẮN MOTOR 1000*400*6MM, nhôm 6mm | E81: =VLOOKUP(D81,'KHO TNJ'!$B$6:$C1071,2,FALSE) -> CX1VVU0590 | G81: Cái | H81: 1
D82: GIÁ ĐỠ HỘP GIẢM TỐC 166.2*85*30*MM, nhôm 5052 4mm | E82: =VLOOKUP(D82,'KHO TNJ'!$B$6:$C1071,2,FALSE) -> CX1VVU0574 | G82: Cái | H82: 2
D83: Bulong inox 304 M10x25 | E83: =VLOOKUP(D83,'KHO TNJ'!$B$6:$C1071,2,FALSE) -> CX1NOA0430 | G83: Cái | H83: 4
D84: Tán inox 304 M10 | E84: =VLOOKUP(D84,'KHO TNJ'!$B$6:$C1071,2,FALSE) -> CX1NOA0001 | G84: Cái | H84: 4
D85: Long Đền inox 304 M10x21, dày 1mm | E85: =VLOOKUP(D85,'KHO TNJ'!$B$6:$C1071,2,FALSE) -> CX1NOA0178 | G85: Cái | H85: 8
A86: Inlet piping | B86: M30A60-05 | C86: 1 | D86: Mặt bích vuông DN80 inox 304. NSX: Thái Bình Minh | E86: =VLOOKUP(D86,'KHO TNJ'!$B$6:$C1071,2,FALSE) -> CX1TBM0393 | G86: Cái | H86: 1
D87: Ống inox 304 90x5.0mm DN80 | E87: =VLOOKUP(D87,'KHO TNJ'!$B$6:$C1071,2,FALSE) -> CX1NOA0382 | G87: mm | H87: 1030
D88: Tán inox 304 M12 | E88: =VLOOKUP(D88,'KHO TNJ'!$B$6:$C1071,2,FALSE) -> CX1NOA0025 | G88: cái | H88: 12
D89: Mặt bích tròn DN80 inox 304. NSX: Thái Bình Minh | E89: =VLOOKUP(D89,'KHO TNJ'!$B$6:$C1071,2,FALSE) -> CX1TBM0392 | G89: Cái | H89: 2
A90: Outlet piping | B90: M30A60-06 | C90: 1 | D90: Mặt bích vuông DN80 inox 304. NSX: Thái Bình Minh | E90: =VLOOKUP(D90,'KHO TNJ'!$B$6:$C1071,2,FALSE) -> CX1TBM0393 | G90: Cái | H90: 1
D91: Ron (Gioăng) Teflon DN80 | E91: =VLOOKUP(D91,'KHO TNJ'!$B$6:$C1071,2,FALSE) -> CX1NOA0377 | G91: Cái | H91: 1
D92: Co hàn 45° Inox 304 DN80 SCH40 | E92: =VLOOKUP(D92,'KHO TNJ'!$B$6:$C1071,2,FALSE) -> CX1NOA0398 | G92: Cái | H92: 0.5
D93: Măng xông Inox 304 DN80 | E93: =VLOOKUP(D93,'KHO TNJ'!$B$6:$C1071,2,FALSE) -> CX1NOA0378 | G93: Cái | H93: 0.5
D94: Co hàn 90 Inox 304 DN80 SCH40 | E94: =VLOOKUP(D94,'KHO TNJ'!$B$6:$C1071,2,FALSE) -> CX1NOA0379 | G94: Cái | H94: 1
D95: Bulong thép đen M12x50 | E95: =VLOOKUP(D95,'KHO TNJ'!$B$6:$C1071,2,FALSE) -> CX1NOA0303 | G95: Cái | H95: 4
A96: Đĩa tang | B96: M30A60-02 | C96: 2 | D96: TANG TRỐNG ɸ1117.6*ɸ90*4MM, nhôm 5052 | E96: =VLOOKUP(D96,'KHO TNJ'!$B$6:$C1071,2,FALSE) -> CX1VVU0577 | G96: Cái | H96: 2
D97: Long đền inox 304 M12x26x1mm | E97: =VLOOKUP(D97,'KHO TNJ'!$B$6:$C1071,2,FALSE) -> CX1NOA0277 | G97: Cái | H97: 8
D98: Bulong Inox 304 M12x30 | E98: =VLOOKUP(D98,'KHO TNJ'!$B$6:$C1071,2,FALSE) -> CX1NOA0010 | G98: Cái | H98: 8
D99: Nhôm tròn đặc: phi 10mm | E99: =VLOOKUP(D99,'KHO TNJ'!$B$6:$C1071,2,FALSE) -> CX1NOA0543 | G99: mm | H99: 7364
...

Sheet HRS20A6003
A8: CÔNG TY TNHH THƯƠNG MẠI DỊCH VỤ TECHNOJET
D15: BẢNG ĐỊNH MỨC VẬT TƯ - NHÂN CÔNG
D16: SẢN XUẤT 1 BỘ HOSE REEL SINGLE WRAP 2 INCH 60 FEETS
D17: MODEL: HRS20A6003
I62: Số phát hành:
I63: TP. Hồ Chí Minh, ngày 21 tháng 11 năm 2025.
A66: PHẦN 1: Phần Định mức Vật tư-Nguyên vật liệu sản xuất
A67: 1.1 DINH_MUC_VAT_TU_SAN_XUAT
A68: Tên cụm chị tiết | B68: Mã số chi tiết/ bản vẽ | C68: Số lượng cụm chi tiết | D68: Tên vật tư/NVL dùng để sx | E68: Mã kho | F68: Hình ảnh NVL | G68: Đơn vị theo thiết kế | H68: Số lượng theo thiết kế | I68: Đơn vị hệ thống | J68: Tỉ trọng chuyển đổi | K68: Số lượng sau chuyển đổi | L68: Ghi chú
A69: KHUNG NHÔM | B69: S20A60-03 | C69: 1 | D69: Nhôm V 50x50x5mm, THÔ, KHÔNG XI | E69: =VLOOKUP(D69,'KHO TNJ'!$B$6:$C1072,2,FALSE) -> CX1NOA0065 | G69: mm | H69: 680
D70: Nhôm hộp 50x50x5mm, THÔ | E70: =VLOOKUP(D70,'KHO TNJ'!$B$6:$C1072,2,FALSE) -> CX1NOA0109 | G70: mm | H70: 6210
D71: Nhôm hộp 25x50x4mm, THÔ | E71: =VLOOKUP(D71,'KHO TNJ'!$B$6:$C1072,2,FALSE) -> CX1NOA0110 | G71: mm | H71: 1275
D72: Ống inox 304 bóng 42,7x2mm | E72: =VLOOKUP(D72,'KHO TNJ'!$B$6:$C1072,2,FALSE) -> CX1NOA0404 | G72: mm | H72: 440
D73: Nhựa POM dạng thanh tròn đặc, màu trắng, DN40 | E73: =VLOOKUP(D73,'KHO TNJ'!$B$6:$C1072,2,FALSE) -> CX1NOA0149 | G73: mm | H73: 92
D74: Cây ty inox 304 (Cây tròn đặc): Phi 12mm | E74: =VLOOKUP(D74,'KHO TNJ'!$B$6:$C1072,2,FALSE) -> CX1NOA0151 | G74: mm | H74: 750
D75: Bulong Inox 304 M12x70 | E75: =VLOOKUP(D75,'KHO TNJ'!$B$6:$C1072,2,FALSE) -> CX1NOA0115 | G75: Cái | H75: 3
D76: Bulong inox 304 M12x80 | E76: =VLOOKUP(D76,'KHO TNJ'!$B$6:$C1072,2,FALSE) -> CX1NOA0431 | G76: Cái | H76: 3
D77: Bulong Inox 304 M12x40 | E77: =VLOOKUP(D77,'KHO TNJ'!$B$6:$C1072,2,FALSE) -> CX1NOA0011 | G77: Cái | H77: 3
D78: Tán inox 304 M12 | E78: =VLOOKUP(D78,'KHO TNJ'!$B$6:$C1072,2,FALSE) -> CX1NOA0025 | G78: mm | H78: 17
D79: Bạc đạn (Vòng bi) CN 6001-DDU V3 RBI | E79: =VLOOKUP(D79,'KHO TNJ'!$B$6:$C1072,2,FALSE) -> CX1RBI0427 | G79: Cái | H79: 4
D80: Long đền inox 304 M12x26x1mm | E80: =VLOOKUP(D80,'KHO TNJ'!$B$6:$C1072,2,FALSE) -> CX1NOA0277 | G80: Cái | H80: 34
D81: TẤM GIÁ ĐỠ MOTOR 865*400*6MM, nhôm 6mm | E81: =VLOOKUP(D81,'KHO TNJ'!$B$6:$C1072,2,FALSE) -> CX1VVU0575 | G81: Cái | H81: 1
D82: GIÁ ĐỠ HỘP GIẢM TỐC 166.2*85*30*MM, nhôm 5052 4mm | E82: =VLOOKUP(D82,'KHO TNJ'!$B$6:$C1072,2,FALSE) -> CX1VVU0574 | G82: Cái | H82: 2
D83: Bulong inox 304 M10x25 | E83: =VLOOKUP(D83,'KHO TNJ'!$B$6:$C1072,2,FALSE) -> CX1NOA0430 | G83: Cái | H83: 4
D84: Tán inox 304 M10 | E84: =VLOOKUP(D84,'KHO TNJ'!$B$6:$C1072,2,FALSE) -> CX1NOA0001 | G84: Cái | H84: 4
D85: Long đền inox 304 M10x21, dày 1mm | E85: =VLOOKUP(D85,'KHO TNJ'!$B$6:$C1072,2,FALSE) -> CX1NOA0178 | G85: Cái | H85: 8
A86: INLET PIPING | C86: 1 | D86: Mặt bích vuông 115 inox 304 có rãnh 2 inch | E86: =VLOOKUP(D86,'KHO TNJ'!$B$6:$C1072,2,FALSE) -> CX1TBM0142 | G86: Cái | H86: 1
D87: Ống inox 304 60x4.0mm | E87: =VLOOKUP(D87,'KHO TNJ'!$B$6:$C1072,2,FALSE) -> CX1NOA0022 | G87: mm | H87: 685
D88: Tán inox 304 M12 | E88: =VLOOKUP(D88,'KHO TNJ'!$B$6:$C1072,2,FALSE) -> CX1NOA0025 | G88: Cái | H88: 12
D89: Mặt bích tròn DN50 | E89: =VLOOKUP(D89,'KHO TNJ'!$B$6:$C1072,2,FALSE) -> CX1NOA0127 | G89: Cái | H89: 2
A90: OUTLET PIPING | C90: 1 | D90: Mặt bích vuông 115 inox 304 có rãnh 2 inch | E90: =VLOOKUP(D90,'KHO TNJ'!$B$6:$C1072,2,FALSE) -> CX1TBM0142 | G90: Cái | H90: 1
D91: Ron (Gioăng) Teflon DN50 | E91: =VLOOKUP(D91,'KHO TNJ'!$B$6:$C1072,2,FALSE) -> CX1NOA0084 | G91: Cái | H91: 1
D92: Co hàn 45° Inox 304 DN50 SCH40 | E92: =VLOOKUP(D92,'KHO TNJ'!$B$6:$C1072,2,FALSE) -> CX1NOA0376 | G92: Cái | H92: 0.5
D93: Măng xông inox 304 ASME B16.11 nối ren NPT CL3000 2" | E93: =VLOOKUP(D93,'KHO TNJ'!$B$6:$C1072,2,FALSE) -> CX1NOA0547 | G93: Cái | H93: 0.5
D94: Co Hàn 90 Inox 304 DN50 SCH10 | E94: =VLOOKUP(D94,'KHO TNJ'!$B$6:$C1072,2,FALSE) -> CX1NOA0060 | G94: Cái | H94: 1
D95: Bulong thép đen M12X40 | E95: =VLOOKUP(D95,'KHO TNJ'!$B$6:$C1072,2,FALSE) -> CX1NOA0176 | G95: Cái | H95: 4
A96: KHUNG TANG QUAY | B96: S20A60-04-05-06 | C96: 2 | D96: Nhôm hộp 25x25x1.5mm, THÔ | E96: =VLOOKUP(D96,'KHO TNJ'!$B$6:$C1072,2,FALSE) -> CX1NOA0541 | G96: mm | H96: 12964
D97: Nhôm hộp 25x50x2mm, THÔ | E97: =VLOOKUP(D97,'KHO TNJ'!$B$6:$C1072,2,FALSE) -> CX1NOA0506 | G97: mm | H97: 3104
D98: Nhôm la 25x5 mm | E98: =VLOOKUP(D98,'KHO TNJ'!$B$6:$C1072,2,FALSE) -> CX1NOA0507 | G98: mm | H98: 4144
D99: TANG CUỐN (VÒNG NGOÀI CHI TIẾT SỐ 2) 922*461*6MM, nhôm 6mm | E99: =VLOOKUP(D99,'KHO TNJ'!$B$6:$C1072,2,FALSE) -> CX1VVU0593 | G99: Cái | H99: 4
...

Sheet DHRM38A6001
A8: CÔNG TY TNHH THƯƠNG MẠI DỊCH VỤ TECHNOJET
D15: BẢNG ĐỊNH MỨC VẬT TƯ - NHÂN CÔNG
D16: SẢN XUẤT 1 BỘ DUAL HOSE REEL 60FT 3/8"
D17: MODEL: DHRM38A6001
I62: Số phát hành:
I63: TP. Hồ Chí Minh, ngày 21 tháng 11 năm 2025.
A66: PHẦN 1: Phần Định mức Vật tư-Nguyên vật liệu sản xuất
A67: 1.1 DINH_MUC_VAT_TU_SAN_XUAT
A68: Tên cụm chị tiết | B68: Mã số chi tiết/ bản vẽ | C68: Số lượng cụm chi tiết | D68: Tên vật tư/NVL dùng để sx | E68: Mã kho | F68: Hình ảnh NVL | G68: Đơn vị theo thiết kế | H68: Số lượng theo thiết kế | I68: Đơn vị hệ thống | J68: Tỉ trọng chuyển đổi | K68: Số lượng sau chuyển đổi | L68: Ghi chú
A69: KHUNG QUAY | C69: 1 | D69: TANG TRỐNG ɸ620*ɸ35.5*2MM, nhôm 5052 | E69: =VLOOKUP(D69,'KHO TNJ'!$B$6:$C1069,2,FALSE) -> CX1VVU0569 | G69: Cái | H69: 2
D70: Nhôm tròn đặc: phi 6mm | E70: =VLOOKUP(D70,'KHO TNJ'!$B$6:$C1069,2,FALSE) -> CX1NOA0438 | G70: mm | H70: 4214
D71: TẤM TRỐNG 692*82*2MM, nhôm 5052 | E71: =VLOOKUP(D71,'KHO TNJ'!$B$6:$C1069,2,FALSE) -> CX1VVU0568 | G71: Cái | H71: 1
D72: Cây ty inox 304 (Cây tròn Đặc): phi 14mm | E72: =VLOOKUP(D72,'KHO TNJ'!$B$6:$C1069,2,FALSE) -> CX1NOA0546 | G72: mm | H72: 981
D73: Tán inox 304 M10 | E73: =VLOOKUP(D73,'KHO TNJ'!$B$6:$C1069,2,FALSE) -> CX1NOA0001 | G73: Cái | H73: 12
D74: Long Đền inox 304 M10x21, dày 1mm | E74: =VLOOKUP(D74,'KHO TNJ'!$B$6:$C1069,2,FALSE) -> CX1NOA0178 | G74: Cái | H74: 12
D75: Bulong inox 304 M8x20 | E75: =VLOOKUP(D75,'KHO TNJ'!$B$6:$C1069,2,FALSE) -> CX1NOA0498 | G75: Cái | H75: 4
D76: Bulong inox 304 lục giác chìm đầu bằng M8x40 | E76: =VLOOKUP(D76,'KHO TNJ'!$B$6:$C1069,2,FALSE) -> CX1NOA0499 | G76: Cái | H76: 4
D77: Nhôm ống 22x3mm | E77: =VLOOKUP(D77,'KHO TNJ'!$B$6:$C1069,2,FALSE) -> CX1NOA0557 | G77: mm | H77: 176
D78: Long đền inox 304 M8x19x2mm | E78: =VLOOKUP(D78,'KHO TNJ'!$B$6:$C1069,2,FALSE) -> CX1NOA0455 | G78: Cái | H78: 13
A79: KHUNG NHÔM | C79: 1 | D79: KHUNG L (CHI TIẾT 1) 500*5*396.5MM, nhôm 5052 5mm | E79: =VLOOKUP(D79,'KHO TNJ'!$B$6:$C1069,2,FALSE) -> CX1VVU0587 | G79: Cái | H79: 1
D80: KHUNG P (CHI TIẾT 1) 500*5*396.5MM, nhôm 5052 5mm | E80: =VLOOKUP(D80,'KHO TNJ'!$B$6:$C1069,2,FALSE) -> CX1VVU0586 | G80: Cái | H80: 1
D81: KHUNG DƯỚI 500*152*5MM, nhôm 5052 5mm | E81: =VLOOKUP(D81,'KHO TNJ'!$B$6:$C1069,2,FALSE) -> CX1VVU0589 | G81: Cái | H81: 1
D82: Bạc đạn (Vòng bi) F&D 6006-2RS | E82: =VLOOKUP(D82,'KHO TNJ'!$B$6:$C1069,2,FALSE) -> CX1F&D0295 | G82: Cái | H82: 2
D83: Ổ đỡ bạc đạn 6006 ɸ71*55*17MM, nhôm | E83: =VLOOKUP(D83,'KHO TNJ'!$B$6:$C1069,2,FALSE) -> CX1KLO0606 | G83: Cái | H83: 2
D84: Phe gài lỗ phi 55mm | E84: =VLOOKUP(D84,'KHO TNJ'!$B$6:$C1069,2,FALSE) -> CX1NOA0456 | G84: Cái | H84: 2
D85: Bulong Inox 304 M10x30 | E85: =VLOOKUP(D85,'KHO TNJ'!$B$6:$C1069,2,FALSE) -> CX1NOA0009 | G85: Cái | H85: 4
D86: Tán inox 304 M10 | E86: =VLOOKUP(D86,'KHO TNJ'!$B$6:$C1069,2,FALSE) -> CX1NOA0001 | G86: Cái | H86: 4
D87: Long Đền inox 304 M10x21, dày 1mm | E87: =VLOOKUP(D87,'KHO TNJ'!$B$6:$C1069,2,FALSE) -> CX1NOA0178 | G87: Cái | H87: 8
A88: INLLET PIPING | C88: 1 | D88: Mặt bích DN25 Inox 125x125x5mm | E88: =VLOOKUP(D88,'KHO TNJ'!$B$6:$C1069,2,FALSE) -> CX1PLO0441 | G88: Cái | H88: 2
D89: Ống inox 304 34x10mm | E89: =VLOOKUP(D89,'KHO TNJ'!$B$6:$C1069,2,FALSE) -> CX1NOA0400 | G89: mm | H89: 193
D90: Ống inox 304 21x5mm | E90: =VLOOKUP(D90,'KHO TNJ'!$B$6:$C1069,2,FALSE) -> CX1NOA0401 | G90: mm | H90: 230
D91: Co 90D inox 304 ASME B16.11 nối ren NPT CL3000 3/8" | E91: =VLOOKUP(D91,'KHO TNJ'!$B$6:$C1069,2,FALSE) -> CX1NOA0482 | G91: Cái | H91: 2
D92: Cây ty inox 304 (Cây tròn đặc): phi 25mm | E92: =VLOOKUP(D92,'KHO TNJ'!$B$6:$C1069,2,FALSE) -> CX1NOA0505 | G92: mm | H92: 7
D93: Phe gài Trục Phi 30 | E93: =VLOOKUP(D93,'KHO TNJ'!$B$6:$C1069,2,FALSE) -> CX1NOA0145 | G93: Cái | H93: 2
A94: BỘ LÒ XO THU HỒI | C94: 1 | D94: HỘP LÒ XO P1 (CHI TIẾT P2) ɸ486*ɸ447*3MM, nhôm 5052 | E94: =VLOOKUP(D94,'KHO TNJ'!$B$6:$C1069,2,FALSE) -> CX1VVU0572 | G94: Cái | H94: 1
D95: HỘP LÒ XO P1 (CHI TIẾT P3) ɸ439*ɸ31*3MM, nhôm 5052 | E95: =VLOOKUP(D95,'KHO TNJ'!$B$6:$C1069,2,FALSE) -> CX1VVU0573 | G95: Cái | H95: 1
D96: Nhôm la 30x3 mm | E96: =VLOOKUP(D96,'KHO TNJ'!$B$6:$C1069,2,FALSE) -> CX1NOA0558 | G96: mm | H96: 1460
D97: Hộp lò xo P2 bằng nhôm phi 486x31x3mm | E97: =VLOOKUP(D97,'KHO TNJ'!$B$6:$C1069,2,FALSE) -> CX1TBM0528 | G97: Cái | H97: 1
D98: LÕI GIỮA LÒ XO ɸ60*30.5*25MM, Inox SS304 | E98: =VLOOKUP(D98,'KHO TNJ'!$B$6:$C1069,2,FALSE) -> CX1HTP0626 | G98: Cái | H98: 1
D99: BÁNH CÓC 242,3*77*25mm | E99: =VLOOKUP(D99,'KHO TNJ'!$B$6:$C1069,2,FALSE) -> CX1HTP0490 | G99: Cái | H99: 1
...

Sheet SCR18A7501_MC_FSM
A8: CÔNG TY TNHH THƯƠNG MẠI DỊCH VỤ TECHNOJET
D15: BẢNG ĐỊNH MỨC VẬT TƯ - NHÂN CÔNG
D16: SẢN XUẤT 1 BỘ STATIC CABLE REEL 1/8"-75FT
D17: MODEL: SCR18A7501-MC-FSM
I62: Số phát hành:
I63: TP. Hồ Chí Minh, ngày 21 tháng 11 năm 2025.
A66: PHẦN 1: Phần Định mức Vật tư-Nguyên vật liệu sản xuất
A67: 1.1 DINH_MUC_VAT_TU_SAN_XUAT
A68: Tên cụm chị tiết | B68: Mã số chi tiết/ bản vẽ | C68: Số lượng cụm chi tiết | D68: Tên vật tư/NVL dùng để sx | E68: Mã kho | F68: Hình ảnh NVL | G68: Đơn vị theo thiết kế | H68: Số lượng theo thiết kế | I68: Đơn vị hệ thống | J68: Tỉ trọng chuyển đổi | K68: Số lượng sau chuyển đổi | L68: Số lượng xk thực tế (20 bộ)
D69: TANG TRỐNG (CHI TIẾT P1) ɸ228.6*44*6MM, nhôm 6mm | E69: =VLOOKUP(D69,'KHO TNJ'!$B$6:$C1071,2,FALSE) -> CX1VVU0592 | G69: Cái | H69: 1 | L69: 20
D70: TANG TRỐNG (CHI TIẾT P2) ɸ228.6*64*6MM, nhôm 6mm | E70: =VLOOKUP(D70,'KHO TNJ'!$B$6:$C1071,2,FALSE) -> CX1VVU0594 | G70: Cái | H70: 1 | L70: 20
D71: Ổ đỡ bạc đạn 6002 | E71: =VLOOKUP(D71,'KHO TNJ'!$B$6:$C1071,2,FALSE) -> CX1NOA0635 | G71: Cái | H71: 1 | L71: 20
D72: Nhôm ống 90x5mm | E72: =VLOOKUP(D72,'KHO TNJ'!$B$6:$C1071,2,FALSE) -> CX1NOA0545 | G72: mm | H72: 40 | L72: 880
D73: KHUNG 200*65*159.9MM, nhôm 5052 5mm | E73: =VLOOKUP(D73,'KHO TNJ'!$B$6:$C1071,2,FALSE) -> CX1VVU0588 | G73: Cái | H73: 1 | L73: 20
D74: KHUNG DẪN HƯỚNG DÂY 147.5*68*50MM, nhôm 5052 5mm | E74: =VLOOKUP(D74,'KHO TNJ'!$B$6:$C1071,2,FALSE) -> CX1VVU0582 | G74: Cái | H74: 1 | L74: 20
D75: Nhôm ống 25x7.5mm | E75: =VLOOKUP(D75,'KHO TNJ'!$B$6:$C1071,2,FALSE) -> CX1NOA0510 | G75: mm | H75: 80 | L75: 820
D76: MẶT BÍCH TRỤC ɸ78*ɸ20.5*5MM, inox 304 | E76: =VLOOKUP(D76,'KHO TNJ'!$B$6:$C1071,2,FALSE) -> CX1VVU0565 | G76: Cái | H76: 1 | L76: 20
D77: Trục ɸ20*15*23.5MM, inox SS304 | E77: =VLOOKUP(D77,'KHO TNJ'!$B$6:$C1071,2,FALSE) -> CX1KLO0607 | G77: Cái | H77: 1 | L77: 20
D78: Vòng Bi CN 6002-DDU ZV3 RBI | E78: =VLOOKUP(D78,'KHO TNJ'!$B$6:$C1071,2,FALSE) -> CX1RBI0563 | G78: Cái | H78: 1 | L78: 20
D79: Bạc đạn (Vòng bi) CN JTEKT (koyo) 626-ZZSM | E79: =VLOOKUP(D79,'KHO TNJ'!$B$6:$C1071,2,FALSE) -> CX1JTE0511 | G79: Cái | H79: 2 | L79: 40
D80: Phe gài lỗ phi 32mm | E80: =VLOOKUP(D80,'KHO TNJ'!$B$6:$C1071,2,FALSE) -> CX1NOA0636 | G80: Cái | H80: 1 | L80: 20
D81: Phe gài trục phi 15mm | E81: =VLOOKUP(D81,'KHO TNJ'!$B$6:$C1071,2,FALSE) -> CX1NOA0637 | G81: Cái | H81: 1 | L81: 21
D82: Bulong inox 304 lục giác chìm đầu bằng M6x70 | E82: =VLOOKUP(D82,'KHO TNJ'!$B$6:$C1071,2,FALSE) -> CX1NOA0638 | G82: Cái | H82: 1 | L82: 14
D83: Bulong inox 304 lục giác chìm đầu bằng M6x80 | E83: 517 | L83: 6
D84: Bulong inox 304 lục giác đầu bằng M8x70 | E84: =VLOOKUP(D84,'KHO TNJ'!$B$6:$C1071,2,FALSE) -> CX1NOA0440 | G84: Cái | H84: 3 | L84: 60
D85: Bulong inox 304 lục giác chìm đầu trụ M5x15 | E85: =VLOOKUP(D85,'KHO TNJ'!$B$6:$C1071,2,FALSE) -> CX1NOA0640 | G85: Cái | H85: 2
D86: Bulong inox 304 lục giác chìm đầu trụ M5x16 | E86: 450 | L86: 40
D87: Tán inox 304 M6 | E87: =VLOOKUP(D87,'KHO TNJ'!$B$6:$C1071,2,FALSE) -> CX1NOA0081 | G87: Cái | H87: 2 | L87: 40
D88: Tán Inox 304 M8 | E88: =VLOOKUP(D88,'KHO TNJ'!$B$6:$C1071,2,FALSE) -> CX1NOA0079 | G88: Cái | H88: 6 | L88: 120
D89: Tán inox 304 M5 | E89: =VLOOKUP(D89,'KHO TNJ'!$B$6:$C1071,2,FALSE) -> CX1NOA0235 | G89: Cái | H89: 2 | L89: 40
D90: Long đền inox 304 M8x1mm | E90: =VLOOKUP(D90,'KHO TNJ'!$B$6:$C1071,2,FALSE) -> CX1NOA0641 | G90: Cái | H90: 3
D91: Long đền inox 304 M8x19x1mm | G91: Cái | L91: 134.8
D92: Long đền inox 304 M5x1mm | E92: =VLOOKUP(D92,'KHO TNJ'!$B$6:$C1071,2,FALSE) -> CX1NOA0642 | G92: Cái | H92: 4
D93: Long đền inox 304 M5x10x1mm | E93: 679 | G93: kg | L93: 0.1
D94: Long đền inox 304 M6x16 mm | E94: =VLOOKUP(D94,'KHO TNJ'!$B$6:$C1071,2,FALSE) -> CX1NOA0278 | G94: Cái | H94: 2 | L94: 175.4
D95: Ống inox 304 Phi 9,6x0,6mm | E95: =VLOOKUP(D95,'KHO TNJ'!$B$6:$C1071,2,FALSE) -> CX1NOA0561 | G95: mm | H95: 37 | L95: 780
D96: Nhôm ống 34x5mm | E96: =VLOOKUP(D96,'KHO TNJ'!$B$6:$C1071,2,FALSE) -> CX1NOA0508 | G96: mm | H96: 21 | L96: 500
D97: Bulong đầu dù vít bake 6x10 | L97: 20
D98: Tay quay ɸ25*80MM, nhôm | E98: CX1KLO0608 | L98: 20
A141: END
...

Sheet GRU30A05-OF-L
A8: CÔNG TY TNHH THƯƠNG MẠI DỊCH VỤ TECHNOJET
D15: BẢNG ĐỊNH MỨC VẬT TƯ - NHÂN CÔNG
D16: SẢN XUẤT 1 BỘ MECHANIMS CLUTCH REDUCER - LEFT SIDE
D17: MODEL: GRU30A05-OF-L
I62: Số phát hành:
I63: TP. Hồ Chí Minh, ngày 21 tháng 11 năm 2025.
A66: PHẦN 1: Phần Định mức Vật tư-Nguyên vật liệu sản xuất
A67: 1.1 DINH_MUC_VAT_TU_SAN_XUAT
A68: Tên cụm chị tiết | B68: Mã số chi tiết/ bản vẽ | C68: Số lượng cụm chi tiết | D68: Tên vật tư/NVL dùng để sx | E68: Mã kho | F68: Hình ảnh NVL | G68: Đơn vị theo thiết kế | H68: Số lượng theo thiết kế | I68: Đơn vị hệ thống | J68: Tỉ trọng chuyển đổi | K68: Số lượng sau chuyển đổi | L68: Số lượng xk thực tế (10 bộ)
D69: Vỏ hộp giảm tốc nhôm 229.8x106.2x76mm. NSX: Kim Lộc | E69: =VLOOKUP(D69,'KHO TNJ'!$B$6:$C1060,2,FALSE) -> CX1KLO0253 | G69: Cái | H69: 1 | L69: 10
D70: Nắp hộp giảm tốc nhôm 82x38x5mm. NSX: Kim Lộc | E70: =VLOOKUP(D70,'KHO TNJ'!$B$6:$C1060,2,FALSE) -> CX1KLO0254 | G70: Cái | H70: 1 | L70: 10
D71: Trục xoay 214.96*30MM, thép | E71: =VLOOKUP(D71,'KHO TNJ'!$B$6:$C1060,2,FALSE) -> CX1KLO0598 | G71: Cái | H71: 1 | L71: 10
D72: ĐĨA RĂNG 45C35, ɸ175.323*52*32.7MM, Thép C45 | E72: =VLOOKUP(D72,'KHO TNJ'!$B$6:$C1060,2,FALSE) -> CX1HTP0612 | G72: Cái | H72: 1 | L72: 10
D73: Nhông xích 40B-12T | E73: =VLOOKUP(D73,'KHO TNJ'!$B$6:$C1060,2,FALSE) -> CX1NOA0130 | G73: Cái | H73: 1 | L73: 10
D74: Bánh răng đồng tốc thép C45: 44 x 30,1 x 27 mm | E74: =VLOOKUP(D74,'KHO TNJ'!$B$6:$C1060,2,FALSE) -> CX1HTP0299 | G74: Cái | H74: 1 | L74: 10
D75: Càng gạt li hợp V2 95.983*6*117.6MM, inox SS304 | E75: =VLOOKUP(D75,'KHO TNJ'!$B$6:$C1060,2,FALSE) -> CX1KLO0599 | G75: Cái | H75: 1 | L75: 10
D76: Ổ giữ bạc đạn V2 104.483*65*21MM, inox SS304 | E76: =VLOOKUP(D76,'KHO TNJ'!$B$6:$C1060,2,FALSE) -> CX1KLO0601 | G76: Cái | H76: 1 | L76: 10
D77: Hộp điều khiển nhôm 78x55x54 mm, dày 3mm. NSX: Kim Lộc | E77: =VLOOKUP(D77,'KHO TNJ'!$B$6:$C1060,2,FALSE) -> CX1KLO0412 | G77: Cái | H77: 1 | L77: 10
D78: Nắp hộp điều khiển 67*50*1MM, nhôm | E78: =VLOOKUP(D78,'KHO TNJ'!$B$6:$C1060,2,FALSE) -> CX1KLO0595 | G78: Cái | H78: 1 | L78: 10
D79: MC – Khâu 2 (Phải) 89.15*16MM, inox SS304 | E79: =VLOOKUP(D79,'KHO TNJ'!$B$6:$C1060,2,FALSE) -> CX1KLO0597 | G79: Cái | H79: 1 | L79: 10
D80: Ti dẫn hướng inox 304 71.66x12mm. NSX: Kim Lộc | E80: =VLOOKUP(D80,'KHO TNJ'!$B$6:$C1060,2,FALSE) -> CX1KLO0414 | G80: Cái | H80: 1 | L80: 10
D81: MC - Khâu 1 inox 304 38x39,294x13mm. NSX: Kim Lộc | E81: =VLOOKUP(D81,'KHO TNJ'!$B$6:$C1060,2,FALSE) -> CX1KLO0422 | G81: Cái | H81: 1 | L81: 10
D82: MC - Khâu 3 inox 304 225x20mm. NSX: Kim Lộc | E82: =VLOOKUP(D82,'KHO TNJ'!$B$6:$C1060,2,FALSE) -> CX1KLO0416 | G82: Cái | H82: 1 | L82: 10
D83: MC - Khâu 4 inox 304 138x20mm. NSX: Kim Lộc | E83: =VLOOKUP(D83,'KHO TNJ'!$B$6:$C1060,2,FALSE) -> CX1KLO0423 | G83: Cái | H83: 1 | L83: 10
D84: PAT ĐIỀU KHIỂN BỘ GIẢM TỐC (PHẢI) 270*125*50MM, nhôm 5052 5mm | E84: =VLOOKUP(D84,'KHO TNJ'!$B$6:$C1060,2,FALSE) -> CX1VVU0584 | G84: Cái | H84: 1 | L84: 10
D85: Chốt định vị ɸ12*45MM, inox SS304 | E85: =VLOOKUP(D85,'KHO TNJ'!$B$6:$C1060,2,FALSE) -> CX1KLO0603 | G85: Cái | H85: 1 | L85: 20
D86: Bạc đạn (Vòng bi) SKF, model: 6206-2RS1/C3 | E86: =VLOOKUP(D86,'KHO TNJ'!$B$6:$C1060,2,FALSE) -> CX1SKF0111 | G86: Cái | H86: 2 | L86: 20
D87: Bạc đạn (VÒNG BI) 6205-2RSC3 ( 6303) | E87: =VLOOKUP(D87,'KHO TNJ'!$B$6:$C1060,2,FALSE) -> CX1SKF0213 | G87: Cái | H87: 1 | L87: 10
D88: Bạc đạn (Vòng bi) 6808 JRLLU, hiệu NTN | E88: =VLOOKUP(D88,'KHO TNJ'!$B$6:$C1060,2,FALSE) -> CX1NTN0250 | G88: Cái | H88: 1 | L88: 10
D89: Phe gài lỗ phi 62mm bằng thép | E89: =VLOOKUP(D89,'KHO TNJ'!$B$6:$C1060,2,FALSE) -> CX1NOA0146 | G89: Cái | H89: 2 | L89: 10
D90: Phe gài lỗ phi 56mm | E90: =VLOOKUP(D90,'KHO TNJ'!$B$6:$C1060,2,FALSE) -> CX1NOA0462 | G90: Cái | H90: 1 | L90: 10
D91: Phe gài Trục Phi 30 | E91: =VLOOKUP(D91,'KHO TNJ'!$B$6:$C1060,2,FALSE) -> CX1NOA0145 | G91: Cái | H91: 2 | L91: 10
D92: Phe gài trục phi 38mm | E92: =VLOOKUP(D92,'KHO TNJ'!$B$6:$C1060,2,FALSE) -> CX1NOA0457 | G92: Cái | H92: 1 | L92: 10
D93: Phe gài trục phi 10mm | E93: =VLOOKUP(D93,'KHO TNJ'!$B$6:$C1060,2,FALSE) -> CX1NOA0309 | G93: Cái | H93: 1 | L93: 10
D94: Tán inox 304 M10 | E94: =VLOOKUP(D94,'KHO TNJ'!$B$6:$C1060,2,FALSE) -> CX1NOA0001 | G94: Cái | H94: 2 | L94: 20
D95: Chốt lavet 8x8x30mm | E95: =VLOOKUP(D95,'KHO TNJ'!$B$6:$C1060,2,FALSE) -> CX1NOA0144 | G95: Cái | H95: 1 | L95: 10
D96: Bulong thép đen lục giác âm M6x5 | E96: =VLOOKUP(D96,'KHO TNJ'!$B$6:$C1060,2,FALSE) -> CX1NOA0148 | G96: Cái | H96: 3
D97: Bulong thép đen lục giác âm M6x6 | L97: 35
D98: Bulong Inox 304 M10x30 | E98: =VLOOKUP(D98,'KHO TNJ'!$B$6:$C1060,2,FALSE) -> CX1NOA0009 | G98: Cái | H98: 4 | L98: 40
D99: Bulong inox 304 M5x25 | E99: =VLOOKUP(D99,'KHO TNJ'!$B$6:$C1060,2,FALSE) -> CX1NOA0643 | G99: Cái | H99: 2 | L99: 10
...

Sheet GRU30A05-OF-R
A8: CÔNG TY TNHH THƯƠNG MẠI DỊCH VỤ TECHNOJET
D15: BẢNG ĐỊNH MỨC VẬT TƯ - NHÂN CÔNG
D16: SẢN XUẤT 1 BỘ MECHANIMS CLUTCH REDUCER - LEFT SIDE
D17: MODEL: GRU30A05-OF-R
I62: Số phát hành:
I63: TP. Hồ Chí Minh, ngày 21 tháng 11 năm 2025.
A66: PHẦN 1: Phần Định mức Vật tư-Nguyên vật liệu sản xuất
A67: 1.1 DINH_MUC_VAT_TU_SAN_XUAT
A68: Tên cụm chị tiết | B68: Mã số chi tiết/ bản vẽ | C68: Số lượng cụm chi tiết | D68: Tên vật tư/NVL dùng để sx | E68: Mã kho | F68: Hình ảnh NVL | G68: Đơn vị theo thiết kế | H68: Số lượng theo thiết kế | I68: Đơn vị hệ thống | J68: Tỉ trọng chuyển đổi | K68: Số lượng sau chuyển đổi | L68: Số lượng xk thực tế
D69: Vỏ hộp giảm tốc nhôm 229.8x106.2x76mm. NSX: Kim Lộc | E69: =VLOOKUP(D69,'KHO TNJ'!$B$6:$C1058,2,FALSE) -> CX1KLO0253 | G69: Cái | H69: 1 | L69: 10
D70: Nắp hộp giảm tốc nhôm 82x38x5mm. NSX: Kim Lộc | E70: =VLOOKUP(D70,'KHO TNJ'!$B$6:$C1058,2,FALSE) -> CX1KLO0254 | G70: Cái | H70: 1 | L70: 10
D71: Trục xoay 214.96*30MM, thép | E71: =VLOOKUP(D71,'KHO TNJ'!$B$6:$C1058,2,FALSE) -> CX1KLO0598 | G71: Cái | H71: 1 | L71: 10
D72: ĐĨA RĂNG 45C35, ɸ175.323*52*32.7MM, Thép C45 | E72: =VLOOKUP(D72,'KHO TNJ'!$B$6:$C1058,2,FALSE) -> CX1HTP0612 | G72: Cái | H72: 1 | L72: 10
D73: Nhông xích 40B-12T | E73: =VLOOKUP(D73,'KHO TNJ'!$B$6:$C1058,2,FALSE) -> CX1NOA0130 | G73: Cái | H73: 1 | L73: 10
D74: Bánh răng đồng tốc thép C45: 44 x 30,1 x 27 mm | E74: =VLOOKUP(D74,'KHO TNJ'!$B$6:$C1058,2,FALSE) -> CX1HTP0299 | G74: Cái | H74: 1 | L74: 10
D75: Càng gạt li hợp V2 95.983*6*117.6MM, inox SS304 | E75: =VLOOKUP(D75,'KHO TNJ'!$B$6:$C1058,2,FALSE) -> CX1KLO0599 | G75: Cái | H75: 1 | L75: 10
D76: Ổ giữ bạc đạn V2 104.483*65*21MM, inox SS304 | E76: =VLOOKUP(D76,'KHO TNJ'!$B$6:$C1058,2,FALSE) -> CX1KLO0601 | G76: Cái | H76: 1 | L76: 10
D77: Hộp điều khiển nhôm 78x55x54 mm, dày 3mm. NSX: Kim Lộc | E77: =VLOOKUP(D77,'KHO TNJ'!$B$6:$C1058,2,FALSE) -> CX1KLO0412 | G77: Cái | H77: 1 | L77: 10
D78: Nắp hộp điều khiển 67*50*1MM, nhôm | E78: =VLOOKUP(D78,'KHO TNJ'!$B$6:$C1058,2,FALSE) -> CX1KLO0595 | G78: Cái | H78: 1 | L78: 10
D79: MC – Khâu 2 (Phải) 89.15*16MM, inox SS304 | E79: =VLOOKUP(D79,'KHO TNJ'!$B$6:$C1058,2,FALSE) -> CX1KLO0597 | G79: Cái | H79: 1 | L79: 10
D80: Ti dẫn hướng inox 304 71.66x12mm. NSX: Kim Lộc | E80: =VLOOKUP(D80,'KHO TNJ'!$B$6:$C1058,2,FALSE) -> CX1KLO0414 | G80: Cái | H80: 1 | L80: 10
D81: MC - Khâu 1 inox 304 38x39,294x13mm. NSX: Kim Lộc | E81: =VLOOKUP(D81,'KHO TNJ'!$B$6:$C1058,2,FALSE) -> CX1KLO0422 | G81: Cái | H81: 1 | L81: 10
D82: MC - Khâu 3 inox 304 225x20mm. NSX: Kim Lộc | E82: =VLOOKUP(D82,'KHO TNJ'!$B$6:$C1058,2,FALSE) -> CX1KLO0416 | G82: Cái | H82: 1 | L82: 10
D83: MC - Khâu 4 inox 304 138x20mm. NSX: Kim Lộc | E83: =VLOOKUP(D83,'KHO TNJ'!$B$6:$C1058,2,FALSE) -> CX1KLO0423 | G83: Cái | H83: 1 | L83: 10
D84: PAT ĐIỀU KHIỂN BỘ GIẢM TỐC (PHẢI) 270*125*50MM, nhôm 5052 5mm | E84: =VLOOKUP(D84,'KHO TNJ'!$B$6:$C1058,2,FALSE) -> CX1VVU0584 | G84: Cái | H84: 1 | L84: 10
D85: Chốt định vị ɸ12*45MM, inox SS304 | E85: =VLOOKUP(D85,'KHO TNJ'!$B$6:$C1058,2,FALSE) -> CX1KLO0603 | G85: Cái | H85: 2 | L85: 20
D86: Bạc đạn (Vòng bi) SKF, model: 6206-2RS1/C3 | E86: =VLOOKUP(D86,'KHO TNJ'!$B$6:$C1058,2,FALSE) -> CX1SKF0111 | G86: Cái | H86: 2 | L86: 20
D87: Bạc đạn (VÒNG BI) 6205-2RSC3 ( 6303) | E87: =VLOOKUP(D87,'KHO TNJ'!$B$6:$C1058,2,FALSE) -> CX1SKF0213 | G87: Cái | H87: 1 | L87: 10
D88: Bạc đạn (Vòng bi) 6808 JRLLU, hiệu NTN | E88: =VLOOKUP(D88,'KHO TNJ'!$B$6:$C1058,2,FALSE) -> CX1NTN0250 | G88: Cái | H88: 1 | L88: 10
D89: Phe gài lỗ phi 62mm bằng thép | E89: =VLOOKUP(D89,'KHO TNJ'!$B$6:$C1058,2,FALSE) -> CX1NOA0146 | G89: Cái | H89: 2 | L89: 14
D90: Phe gài lỗ phi 56mm | E90: =VLOOKUP(D90,'KHO TNJ'!$B$6:$C1058,2,FALSE) -> CX1NOA0462 | G90: Cái | H90: 1 | L90: 10
D91: Phe gài Trục Phi 30 | E91: =VLOOKUP(D91,'KHO TNJ'!$B$6:$C1058,2,FALSE) -> CX1NOA0145 | G91: Cái | H91: 2 | L91: 14
D92: Phe gài trục phi 38mm | E92: =VLOOKUP(D92,'KHO TNJ'!$B$6:$C1058,2,FALSE) -> CX1NOA0457 | G92: Cái | H92: 1 | L92: 10
D93: Phe gài trục 10mm | E93: CX1NOA0309 | G93: Cái | H93: 1 | L93: 10
D94: Chốt lavet 8x8x30mm | E94: =VLOOKUP(D94,'KHO TNJ'!$B$6:$C1058,2,FALSE) -> CX1NOA0144 | G94: Cái | H94: 1 | L94: 10
D95: Bulong thép đen lục giác âm M6x6 | E95: =VLOOKUP(D95,'KHO TNJ'!$B$6:$C1058,2,FALSE) -> CX1NOA0281 | G95: Cái | H95: 3
D96: Bulong thép đen lục giác âm M6x6 | L96: 26
D97: Bulong Inox 304 M10x30 | E97: =VLOOKUP(D97,'KHO TNJ'!$B$6:$C1058,2,FALSE) -> CX1NOA0009 | G97: Cái | H97: 4 | L97: 40
D98: Bulong inox 304 M5x25 | E98: =VLOOKUP(D98,'KHO TNJ'!$B$6:$C1058,2,FALSE) -> CX1NOA0643 | G98: Cái | H98: 2 | L98: 15
D99: Bulong inox 304 lục giác chìm đầu dù M8x40 | E99: =VLOOKUP(D99,'KHO TNJ'!$B$6:$C1058,2,FALSE) -> CX1NOA0447 | G99: Cái | H99: 1 | L99: 4
...

Sheet NH12ESP01-DC (DRAFT)
A8: CÔNG TY TNHH THƯƠNG MẠI DỊCH VỤ TECHNOJET
D15: BẢNG ĐỊNH MỨC VẬT TƯ - NHÂN CÔNG
D16: SẢN XUẤT 1 BỘ NOZZLE HOLDER-DUST CAP
D17: MODEL: NH12ESP01-DC
I62: Số phát hành:
I63: TP. Hồ Chí Minh, ngày 21 tháng 11 năm 2025.
A66: PHẦN 1: Phần Định mức Vật tư-Nguyên vật liệu sản xuất
A67: 1.1 DINH_MUC_VAT_TU_SAN_XUAT
A68: Tên cụm chị tiết | B68: Mã số chi tiết/ bản vẽ | C68: Số lượng cụm chi tiết | D68: Tên vật tư/NVL dùng để sx | E68: Mã kho | F68: Hình ảnh NVL | G68: Đơn vị theo thiết kế | H68: Số lượng theo thiết kế | I68: Đơn vị hệ thống | J68: Tỉ trọng chuyển đổi | K68: Số lượng sau chuyển đổi | L68: Số lượng xk thực tế
D69: Interlock holder chi tiết tĩnh | E69: =VLOOKUP(D69,'KHO TNJ'!$B$6:$C1060,2,FALSE) -> #N/A | G69: Cái | H69: 1
D70: INTERLOCK HOLDER SEP REV 4 PART2 | E70: =VLOOKUP(D70,'KHO TNJ'!$B$6:$C1060,2,FALSE) -> #N/A | G70: Cái | H70: 1
D71: IH SEP REV 4 PART3 (top bracket) | E71: =VLOOKUP(D71,'KHO TNJ'!$B$6:$C1060,2,FALSE) -> #N/A | G71: Cái | H71: 1
D72: IH SEP04 CONTROL HANDLE #PART1 | E72: =VLOOKUP(D72,'KHO TNJ'!$B$6:$C1060,2,FALSE) -> #N/A | G72: Cái | H72: 1
D73: IH SEP04 LOCK BLOCK ASS'Y # PART1 | E73: =VLOOKUP(D73,'KHO TNJ'!$B$6:$C1060,2,FALSE) -> #N/A | G73: Cái | H73: 1
D74: IH SEP04 LOCK BLOCK ASS'Y # PART12 | E74: =VLOOKUP(D74,'KHO TNJ'!$B$6:$C1060,2,FALSE) -> #N/A | G74: Cái | H74: 1
D75: Ống inox 304 đúc 17,1 x 3,2mm | E75: =VLOOKUP(D75,'KHO TNJ'!$B$6:$C1060,2,FALSE) -> CX1NOA0513 | G75: Mét | H75: 0.026 | K75: =H75*14*1.05 -> 0.3822 | L75: 0.35
D76: Bulong inox 304 lục giác chìm đầu trụ M6x50 | E76: =VLOOKUP(D76,'KHO TNJ'!$B$6:$C1060,2,FALSE) -> CX1NOA0452 | G76: Cái | H76: 2 | K76: =H76*14*1.05 -> 29.4 | L76: 28
C77: 3 con của tiêu hao t7 | D77: Bulong Inox 304 lục giác chìm đầu dù M6x16 | E77: CX1NOA0229 | G77: Cái | H77: 7 | K77: =H77*14*1.05 -> 102.9 | L77: =55+3 -> 58
D78: Bulong inox 304 lục giác chìm đầu dù M6x15 | E78: CX1NOA0275 | L78: 41
D79: Tán inox 304 M6 | E79: =VLOOKUP(D79,'KHO TNJ'!$B$6:$C1060,2,FALSE) -> CX1NOA0081 | G79: Cái | H79: 7 | K79: =H79*14*1.05 -> 102.9 | L79: 88
D80: Long đền inox 304 M6x16 mm | E80: =VLOOKUP(D80,'KHO TNJ'!$B$6:$C1060,2,FALSE) -> CX1NOA0278 | G80: Cái | H80: 14 | K80: =H80*14*1.05 -> 205.8 | L80: 182.7
K81: =H81*14*1.05 -> 0
D82: Lò xo nén (inox) đường kính trong 10mm, dày 1mm, dài 300mm | E82: =VLOOKUP(D82,'KHO TNJ'!$B$6:$C1060,2,FALSE) -> CX1NOA0685 | G82: Mét | H82: 0.08 | K82: =H82*14*1.05 -> 1.176 | L82: 1.08
D83: Khớp xoay chi tiết p1 (holder phiên bản có nắp chụp) | E83: =VLOOKUP(D83,'KHO TNJ'!$B$6:$C1060,2,FALSE) -> #N/A | G83: Cái | H83: 1 | K83: =H83*14*1.05 -> 14.7
D84: Khớp xoay chi tiết p2 (holder phiên bản có nắp chụp) | E84: =VLOOKUP(D84,'KHO TNJ'!$B$6:$C1060,2,FALSE) -> #N/A | G84: Cái | H84: 1 | K84: =H84*14*1.05 -> 14.7
D85: Tán Inox 304 M8 | E85: =VLOOKUP(D85,'KHO TNJ'!$B$6:$C1060,2,FALSE) -> CX1NOA0079 | G85: Cái | H85: 4 | K85: =H85*14*1.05 -> 58.8 | L85: 56
C86: nk lại | D86: Long_Đền 304 M8x19x1 | E86: =VLOOKUP(D86,'KHO TNJ'!$B$6:$C1060,2,FALSE) -> CX1NOA0680 | G86: Cái | H86: 8 | K86: =H86*14*1.05 -> 117.6 | L86: =131.4-96.2 -> 35.2
D87: Interlock holder - Pat lò xo | E87: =VLOOKUP(D87,'KHO TNJ'!$B$6:$C1060,2,FALSE) -> #N/A | G87: Cái | H87: 1 | K87: =H87*14*1.05 -> 14.7
D88: Interlock holder- Pat nắp chụp bụi | E88: =VLOOKUP(D88,'KHO TNJ'!$B$6:$C1060,2,FALSE) -> #N/A | G88: Cái | H88: 1 | K88: =H88*14*1.05 -> 14.7
D89: Bulong lục giác chìm đầu dù M8x15, inox 304 | E89: =VLOOKUP(D89,'KHO TNJ'!$B$6:$C1060,2,FALSE) -> CX1NOA0305 | G89: Cái | H89: 2 | K89: =H89*14*1.05 -> 29.4 | L89: 16
D90: Bulong inox 304 lục giác chìm đầu dù M8x16 | E90: =VLOOKUP(D90,'KHO TNJ'!$B$6:$C1060,2,FALSE) -> CX1NOA0688 | L90: 12
C91: xuất vào 632 | D91: Cây ty inox 304 (Cây tròn đặc): phi 10mm | E91: =VLOOKUP(D91,'KHO TNJ'!$B$6:$C1060,2,FALSE) -> CX1NOA0402 | G91: Mét | H91: 0.262 | K91: =H91*14*1.05 -> 3.8514 | L91: 3.89
B92: nk 2 cái | C92: dùng cho 8 bộ sau, nk lại 2 cái | D92: Phe gài trục phi 10mm | E92: =VLOOKUP(D92,'KHO TNJ'!$B$6:$C1060,2,FALSE) -> CX1NOA0309 | G92: Cái | H92: 2 | K92: =H92*8*1.05 -> 16.8 | L92: =18-2 -> 16
G93: Cái | K93: =H93*14*1.05 -> 0
B94: đã nk lại | C94: xuất cho bộ ko nắp, nên mã này cho bộ có nắp vượt định mức, nk lại 12 con | D94: Bulong inox 304 lục giác chìm đầu dù M6x40 | E94: =VLOOKUP(D94,'KHO TNJ'!$B$6:$C1060,2,FALSE) -> CX1NOA0689 | H94: 0 | K94: =H94*14*1.05 -> 0 | L94: =12-12 -> 0
B95: Chốt Chẻ Thép Mạ Kẽm 7 Màu (Chốt Bi) phi2x30mm | C95: dùng cho 6 bộ đầu | D95: Chốt chẻ inox 304 phi 2mm | E95: =VLOOKUP(D95,'KHO TNJ'!$B$6:$C1060,2,FALSE) -> CX1NOA0644 | H95: 2 | K95: =H95*6*1.05 -> 12.6 | L95: 12
K96: =H96*14*1.05 -> 0
A131: END
A132: 1.2 Tổng hợp nguyên vật liệu sản xuất.

Sheet NH12ESP01 (DRAFT)
A8: CÔNG TY TNHH THƯƠNG MẠI DỊCH VỤ TECHNOJET
D15: BẢNG ĐỊNH MỨC VẬT TƯ - NHÂN CÔNG
D16: SẢN XUẤT 1 BỘ NOZZLE HOLDER
D17: MODEL: NH12ESP01
I62: Số phát hành:
I63: TP. Hồ Chí Minh, ngày 21 tháng 11 năm 2025.
A66: PHẦN 1: Phần Định mức Vật tư-Nguyên vật liệu sản xuất
A67: 1.1 DINH_MUC_VAT_TU_SAN_XUAT
A68: Tên cụm chị tiết | B68: Mã số chi tiết/ bản vẽ | C68: Số lượng cụm chi tiết | D68: Tên vật tư/NVL dùng để sx | E68: Mã kho | F68: Hình ảnh NVL | G68: Đơn vị theo thiết kế | H68: Số lượng theo thiết kế | I68: Đơn vị hệ thống | J68: Tỉ trọng chuyển đổi | K68: Số lượng sau chuyển đổi | L68: Số lượng xk thực tế
D69: Interlock holder chi tiết tĩnh | E69: =VLOOKUP(D69,'KHO TNJ'!$B$6:$C1058,2,FALSE) -> #N/A | G69: Cái | H69: 1
D70: INTERLOCK HOLDER SEP REV 4 PART2 | E70: =VLOOKUP(D70,'KHO TNJ'!$B$6:$C1058,2,FALSE) -> #N/A | G70: Cái | H70: 1
D71: IH SEP REV 4 PART3 (top bracket) | E71: =VLOOKUP(D71,'KHO TNJ'!$B$6:$C1058,2,FALSE) -> #N/A | G71: Cái | H71: 1
D72: IH SEP04 CONTROL HANDLE #PART1 | E72: =VLOOKUP(D72,'KHO TNJ'!$B$6:$C1058,2,FALSE) -> #N/A | G72: Cái | H72: 1
D73: IH SEP04 LOCK BLOCK ASS'Y # PART1 | E73: =VLOOKUP(D73,'KHO TNJ'!$B$6:$C1058,2,FALSE) -> #N/A | G73: Cái | H73: 1
D74: IH SEP04 LOCK BLOCK ASS'Y # PART12 | E74: =VLOOKUP(D74,'KHO TNJ'!$B$6:$C1058,2,FALSE) -> #N/A | G74: Cái | H74: 1
D75: Ống inox 304 đúc 17,1 x 3,2mm | E75: =VLOOKUP(D75,'KHO TNJ'!$B$6:$C1058,2,FALSE) -> CX1NOA0513 | G75: Mét | H75: 0.026 | K75: =H75*14*1.05 -> 0.3822 | L75: 0.37
D76: Bulong inox 304 lục giác chìm đầu dù M6x40 | E76: =VLOOKUP(D76,'KHO TNJ'!$B$6:$C1058,2,FALSE) -> CX1NOA0689 | G76: Cái | H76: 2 | K76: =H76*14*1.05 -> 29.4 | L76: 28
D77: Bulong Inox 304 lục giác chìm đầu dù M6x16 | E77: =VLOOKUP(D77,'KHO TNJ'!$B$6:$C1058,2,FALSE) -> CX1NOA0229 | G77: Cái | H77: 5 | K77: =H77*14*1.05 -> 73.5 | L77: 70
D78: Tán inox 304 M6 | E78: =VLOOKUP(D78,'KHO TNJ'!$B$6:$C1058,2,FALSE) -> CX1NOA0081 | G78: Cái | H78: 5 | K78: =H78*14*1.05 -> 73.5 | L78: 72
D79: Long đền inox 304 M6x16 mm | E79: =VLOOKUP(D79,'KHO TNJ'!$B$6:$C1058,2,FALSE) -> CX1NOA0278 | G79: Cái | H79: 10 | K79: =H79*14*1.05 -> 147 | L79: 106.85
D80: Lò xo nén (inox) đường kính trong 10mm, dày 1mm, dài 300mm | E80: =VLOOKUP(D80,'KHO TNJ'!$B$6:$C1058,2,FALSE) -> CX1NOA0685 | G80: Mét | H80: 0.08 | K80: =H80*14*1.05 -> 1.176 | L80: 1.08
C81: 632 | D81: Cây ty inox 304 (Cây tròn đặc): phi 10mm | E81: =VLOOKUP(D81,'KHO TNJ'!$B$6:$C1058,2,FALSE) -> CX1NOA0402 | G81: Mét | H81: 0.262 | K81: =H81*14*1.05 -> 3.8514 | L81: 4.34
B82: nk lại 2 cái | C82: dùng cho 8 bộ sau, nk lại 2 cái | D82: Phe gài trục phi 10mm | E82: =VLOOKUP(D82,'KHO TNJ'!$B$6:$C1058,2,FALSE) -> CX1NOA0309 | G82: Cái | H82: 2 | K82: =H82*8*1.05 -> 16.8 | L82: =18-2 -> 16
B83: nk lại 13 con, 12 con cho mã k nắp, 1 con cho bộ mẫu thử | C83: nk lại, món này xuất dư bên bộ ko nắp | D83: Tán Inox 304 M8 | E83: =VLOOKUP(D83,'KHO TNJ'!$B$6:$C1058,2,FALSE) -> CX1NOA0079 | H83: 0 | K83: =H83*14*1.05 -> 0 | L83: =12-12 -> 0
D84: Long_Đền 304 M8x19x1 | E84: =VLOOKUP(D84,'KHO TNJ'!$B$6:$C1058,2,FALSE) -> CX1NOA0680 | K84: =H84*14*1.05 -> 0 | L84: 33.7
C85: dùng cho 6 bộ đầu | D85: Chốt chẻ inox 304 phi 2mm | E85: =VLOOKUP(D85,'KHO TNJ'!$B$6:$C1058,2,FALSE) -> CX1NOA0644 | H85: 2 | K85: =H85*6*1.05 -> 12.6 | L85: 12
B86: nk lại 12 con | D86: Bulong inox 304 lục giác chìm đầu dù M8x16 | E86: =VLOOKUP(D86,'KHO TNJ'!$B$6:$C1058,2,FALSE) -> CX1NOA0688 | L86: =12-12 -> 0
A129: END
A130: 1.2 Tổng hợp nguyên vật liệu sản xuất.
B131: STT | C131: Tên vật tư | D131: Mã kho | E131: Hình ảnh chi tiết | F131: Đơn vị | G131: Số lượng | H131: Hao hụt theo % | I131: Số lượng hao hụt theo % | J131: Số lượng thực tế/ 1bộ | K131: Số lượng cho dự án | L131: Xuất kho thực tế
A132: VAT_TU_GIAN_TIEP

Sheet BOM_TONG_HOP
M1: SHEET | N1: STATUS | O1: LAST UPDATE
M2: HRM30A6001 | N2: 🟢 Updated | O2: 46309.673
M3: HRS20A6003 | N3: 🔴 Outdated | O3: 46309.592
M4: DHRM38A6001 | N4: 🔴 Outdated | O4: 46310.382
M5: SCR18A7501_MC_FSM | N5: 🔴 Outdated | O5: 46308.673
M6: GRU30A05-OF-L | N6: 🔴 Outdated | O6: 46310.406
M7: GRU30A05-OF-R | N7: 🔴 Outdated | O7: 46310.409
A8: CÔNG TY TNHH THƯƠNG MẠI DỊCH VỤ TECHNOJET
D12: BẢNG TỔNG HỢP NGUYÊN VẬT LIỆU
A13: SẢN XUẤT CÁC PHỤ KIỆN CHO DỰ ÁN 10 XE DISPENSER FSM
A15: 1.2 Tổng hợp nguyên vật liệu sản xuất.
A16: Chủng loại | B16: STT | C16: Tên vật tư | D16: Mã kho | E16: Đơn vị | F16: Tồn kho | G16: Số lượng cần | H16: Số lượng mua | I16: Số lượng đã xuất | J16: Số lượng chưa xuất | K16: Kho khả dụng | L16: Ghi chú
B17: 1 | C17: Bạc đạn (Vòng bi) 696 ZZ 2RS | D17: CX1DPI0445 | E17: Cái | F17: =IFERROR(VLOOKUP(D17,'KHO TNJ'!$C$6:$E$100000,3,FALSE),0)+IF(I17="",0,I17) -> 0 | G17: 80 | H17: =IF($F17<$G17,$G17-$F17,"") -> 80 | I17: 0 | J17: =G17-I17 -> 80
B18: 2 | C18: Bạc đạn (VÒNG BI) 6205-2RSC3 ( 6303) | D18: CX1SKF0213 | E18: Cái | F18: =IFERROR(VLOOKUP(D18,'KHO TNJ'!$C$6:$E$100000,3,FALSE),0)+IF(I18="",0,I18) -> 2 | G18: 20 | H18: =IF($F18<$G18,$G18-$F18,"") -> 18 | I18: 0 | J18: =G18-I18 -> 20
B19: 3 | C19: Bạc đạn (Vòng bi) 6808 JRLLU, hiệu NTN | D19: CX1NTN0250 | E19: Cái | F19: =IFERROR(VLOOKUP(D19,'KHO TNJ'!$C$6:$E$100000,3,FALSE),0)+IF(I19="",0,I19) -> 0 | G19: 20 | H19: =IF($F19<$G19,$G19-$F19,"") -> 20 | I19: 0 | J19: =G19-I19 -> 20
B20: 4 | C20: Bạc đạn (Vòng bi) CN 6000-DDU ZV3 RBI | D20: CX1RBI0426 | E20: Cái | F20: =IFERROR(VLOOKUP(D20,'KHO TNJ'!$C$6:$E$100000,3,FALSE),0)+IF(I20="",0,I20) -> 160 | G20: 80 | H20: =IF($F20<$G20,$G20-$F20,"") | I20: 80 | J20: =G20-I20 -> 0
B21: 5 | C21: Bạc đạn (Vòng bi) CN 6001-DDU V3 RBI | D21: CX1RBI0427 | E21: Cái | F21: =IFERROR(VLOOKUP(D21,'KHO TNJ'!$C$6:$E$100000,3,FALSE),0)+IF(I21="",0,I21) -> 280 | G21: 140 | H21: =IF($F21<$G21,$G21-$F21,"") | I21: 140 | J21: =G21-I21 -> 0
B22: 6 | C22: Bạc đạn (Vòng bi) CN JTEKT (koyo) 626-ZZSM | D22: CX1JTE0511 | E22: Cái | F22: =IFERROR(VLOOKUP(D22,'KHO TNJ'!$C$6:$E$100000,3,FALSE),0)+IF(I22="",0,I22) -> 80 | G22: 40 | H22: =IF($F22<$G22,$G22-$F22,"") | I22: 40 | J22: =G22-I22 -> 0
B23: 7 | C23: Bạc đạn (Vòng bi) F&D 6006-2RS | D23: CX1F&D0295 | E23: Cái | F23: =IFERROR(VLOOKUP(D23,'KHO TNJ'!$C$6:$E$100000,3,FALSE),0)+IF(I23="",0,I23) -> 20 | G23: 20 | H23: =IF($F23<$G23,$G23-$F23,"") | I23: 0 | J23: =G23-I23 -> 20
B24: 8 | C24: Bạc đạn (Vòng bi) SKF, model: 6206-2RS1/C3 | D24: CX1SKF0111 | E24: Cái | F24: =IFERROR(VLOOKUP(D24,'KHO TNJ'!$C$6:$E$100000,3,FALSE),0)+IF(I24="",0,I24) -> 0 | G24: 40 | H24: =IF($F24<$G24,$G24-$F24,"") -> 40 | I24: 0 | J24: =G24-I24 -> 40
B25: 9 | C25: BÁNH CÓC 242,3*77*25mm | D25: CX1HTP0490 | E25: Cái | F25: =IFERROR(VLOOKUP(D25,'KHO TNJ'!$C$6:$E$100000,3,FALSE),0)+IF(I25="",0,I25) -> 0 | G25: 10 | H25: =IF($F25<$G25,$G25-$F25,"") -> 10 | I25: 0 | J25: =G25-I25 -> 10
B26: 10 | C26: Bánh răng đồng tốc thép C45: 44 x 30,1 x 27 mm | D26: CX1HTP0299 | E26: Cái | F26: =IFERROR(VLOOKUP(D26,'KHO TNJ'!$C$6:$E$100000,3,FALSE),0)+IF(I26="",0,I26) -> 0 | G26: 21 | H26: =IF($F26<$G26,$G26-$F26,"") -> 21 | I26: 0 | J26: =G26-I26 -> 21
B27: 11 | C27: Bulong inox 304 lục giác chìm đầu bằng M6x70 | D27: CX1NOA0638 | E27: Cái | F27: =IFERROR(VLOOKUP(D27,'KHO TNJ'!$C$6:$E$100000,3,FALSE),0)+IF(I27="",0,I27) -> 50 | G27: 21 | H27: =IF($F27<$G27,$G27-$F27,"") | I27: 0 | J27: =G27-I27 -> 21
B28: 12 | C28: Bulong inox 304 lục giác chìm đầu bằng M8x40 | D28: CX1NOA0499 | E28: Cái | F28: =IFERROR(VLOOKUP(D28,'KHO TNJ'!$C$6:$E$100000,3,FALSE),0)+IF(I28="",0,I28) -> 42 | G28: 31.5 | H28: =IF($F28<$G28,$G28-$F28,"") | I28: 0 | J28: =G28-I28 -> 31.5
... B214: 10 | C214: Tem inox Ru lô (Hose reel Name plate) | D214: CX1PLO0092 | E214: Cái | F214: =IFERROR(VLOOKUP(D214,'KHO TNJ'!$C$6:$E$100000,3,FALSE),0)+IF(I214="",0,I214) -> 0 | G214: 50 | H214: =IF($F214<$G214,$G214-$F214,"") -> 50 | I214: 0 | J214: =G214-I214 -> 50
F215: =IFERROR(VLOOKUP(D215,'KHO TNJ'!$C$6:$E$100000,3,FALSE),0)+IF(I215="",0,I215) -> 0 | H215: =IF($F215<$G215,$G215-$F215,"") | J215: =G215-I215 -> 0
F216: =IFERROR(VLOOKUP(D216,'KHO TNJ'!$C$6:$E$100000,3,FALSE),0)+IF(I216="",0,I216) -> 0 | H216: =IF($F216<$G216,$G216-$F216,"") | J216: =G216-I216 -> 0
F217: =IFERROR(VLOOKUP(D217,'KHO TNJ'!$C$6:$E$100000,3,FALSE),0)+IF(I217="",0,I217) -> 0 | H217: =IF($F217<$G217,$G217-$F217,"") | J217: =G217-I217 -> 0
F218: =IFERROR(VLOOKUP(D218,'KHO TNJ'!$C$6:$E$100000,3,FALSE),0)+IF(I218="",0,I218) -> 0 | H218: =IF($F218<$G218,$G218-$F218,"") | J218: =G218-I218 -> 0
F219: =IFERROR(VLOOKUP(D219,'KHO TNJ'!$C$6:$E$100000,3,FALSE),0)+IF(I219="",0,I219) -> 0 | H219: =IF($F219<$G219,$G219-$F219,"") | J219: =G219-I219 -> 0
F220: =IFERROR(VLOOKUP(D220,'KHO TNJ'!$C$6:$E$100000,3,FALSE),0)+IF(I220="",0,I220) -> 0 | H220: =IF($F220<$G220,$G220-$F220,"") | J220: =G220-I220 -> 0
F221: =IFERROR(VLOOKUP(D221,'KHO TNJ'!$C$6:$E$100000,3,FALSE),0)+IF(I221="",0,I221) -> 0 | H221: =IF($F221<$G221,$G221-$F221,"") | J221: =G221-I221 -> 0
F222: =IFERROR(VLOOKUP(D222,'KHO TNJ'!$C$6:$E$100000,3,FALSE),0)+IF(I222="",0,I222) -> 0 | H222: =IF($F222<$G222,$G222-$F222,"") | J222: =G222-I222 -> 0
F223: =IFERROR(VLOOKUP(D223,'KHO TNJ'!$C$6:$E$100000,3,FALSE),0)+IF(I223="",0,I223) -> 0 | H223: =IF($F223<$G223,$G223-$F223,"") | J223: =G223-I223 -> 0
F224: =IFERROR(VLOOKUP(D224,'KHO TNJ'!$C$6:$E$100000,3,FALSE),0)+IF(I224="",0,I224) -> 0 | H224: =IF($F224<$G224,$G224-$F224,"") | J224: =G224-I224 -> 0
F225: =IFERROR(VLOOKUP(D225,'KHO TNJ'!$C$6:$E$100000,3,FALSE),0)+IF(I225="",0,I225) -> 0 | H225: =IF($F225<$G225,$G225-$F225,"") | J225: =G225-I225 -> 0
F226: =IFERROR(VLOOKUP(D226,'KHO TNJ'!$C$6:$E$100000,3,FALSE),0)+IF(I226="",0,I226) -> 0 | H226: =IF($F226<$G226,$G226-$F226,"") | J226: =G226-I226 -> 0
... F993: =IFERROR(VLOOKUP(D993,'KHO TNJ'!$C$6:$E$100000,3,FALSE),0)+IF(I993="",0,I993) -> 0 | H993: =IF($F993<$G993,$G993-$F993,"") | J993: =G993-I993 -> 0

Sheet KHO TNJ
A1: BẢNG TỔNG HỢP MÃ KHO NVL
A5: STT | B5: Tên vật tư | C5: Mã kho | D5: Đơn vị | E5: Số lượng tồn kho | F5: Tỉ trọng khối lượng (cái/gam) | G5: Ghi chú
A6: 1 | B6: =IFERROR(VLOOKUP(C6,INPUT!$A$2:$E$99998,3,FALSE),"") -> Tán inox 304 M10 | C6: CX1NOA0001 | D6: =IFERROR(VLOOKUP(C6,INPUT!$A$2:$D$99998,4,FALSE),"") -> Cái | E6: =IFERROR(VLOOKUP(C6,INPUT!$A$2:$E$99998,5,FALSE),0) -> 763 | F6: =IFERROR(VLOOKUP(C6,INPUT!$H$2:$N2410,7,FALSE),"")
A7: 2 | B7: =IFERROR(VLOOKUP(C7,INPUT!$A$2:$E$99998,3,FALSE),"") -> Tán thép đen M10 đầu 14 | C7: CX1NOA0002 | D7: =IFERROR(VLOOKUP(C7,INPUT!$A$2:$D$99998,4,FALSE),"") -> Cái | E7: =IFERROR(VLOOKUP(C7,INPUT!$A$2:$E$99998,5,FALSE),0) -> 20 | F7: =IFERROR(VLOOKUP(C7,INPUT!$H$2:$N2410,7,FALSE),"")
A8: 3 | B8: =IFERROR(VLOOKUP(C8,INPUT!$A$2:$E$99998,3,FALSE),"") -> Tán inox 304 M13 | C8: CX1NOA0003 | D8: =IFERROR(VLOOKUP(C8,INPUT!$A$2:$D$99998,4,FALSE),"") -> Cái | E8: =IFERROR(VLOOKUP(C8,INPUT!$A$2:$E$99998,5,FALSE),0) -> 0 | F8: =IFERROR(VLOOKUP(C8,INPUT!$H$2:$N2410,7,FALSE),"")
A9: 4 | B9: =IFERROR(VLOOKUP(C9,INPUT!$A$2:$E$99998,3,FALSE),"") -> Tán sắt M13 | C9: CX1NOA0004 | D9: =IFERROR(VLOOKUP(C9,INPUT!$A$2:$D$99998,4,FALSE),"") -> Cái | E9: =IFERROR(VLOOKUP(C9,INPUT!$A$2:$E$99998,5,FALSE),0) -> 0 | F9: =IFERROR(VLOOKUP(C9,INPUT!$H$2:$N2410,7,FALSE),"")
A10: 5 | B10: =IFERROR(VLOOKUP(C10,INPUT!$A$2:$E$99998,3,FALSE),"") -> Tán thép đen M14 | C10: CX1NOA0005 | D10: =IFERROR(VLOOKUP(C10,INPUT!$A$2:$D$99998,4,FALSE),"") -> Cái | E10: =IFERROR(VLOOKUP(C10,INPUT!$A$2:$E$99998,5,FALSE),0) -> 0 | F10: =IFERROR(VLOOKUP(C10,INPUT!$H$2:$N2410,7,FALSE),"")
A11: 6 | B11: =IFERROR(VLOOKUP(C11,INPUT!$A$2:$E$99998,3,FALSE),"") -> Nối ren ngoài sắt kẽm 13mm | C11: CX1NOA0006 | D11: =IFERROR(VLOOKUP(C11,INPUT!$A$2:$D$99998,4,FALSE),"") -> Con | E11: =IFERROR(VLOOKUP(C11,INPUT!$A$2:$E$99998,5,FALSE),0) -> 0 | F11: =IFERROR(VLOOKUP(C11,INPUT!$H$2:$N2410,7,FALSE),"")
A12: 7 | B12: =IFERROR(VLOOKUP(C12,INPUT!$A$2:$E$99998,3,FALSE),"") -> Nối ren ngoài sắt kẽm 21mm | C12: CX1NOA0007 | D12: =IFERROR(VLOOKUP(C12,INPUT!$A$2:$D$99998,4,FALSE),"") -> Con | E12: =IFERROR(VLOOKUP(C12,INPUT!$A$2:$E$99998,5,FALSE),0) -> 0 | F12: =IFERROR(VLOOKUP(C12,INPUT!$H$2:$N2410,7,FALSE),"")
A13: 8 | B13: =IFERROR(VLOOKUP(C13,INPUT!$A$2:$E$99998,3,FALSE),"") -> Bulong Inox 304 M10x20 | C13: CX1NOA0008 | D13: =IFERROR(VLOOKUP(C13,INPUT!$A$2:$D$99998,4,FALSE),"") -> Cái | E13: =IFERROR(VLOOKUP(C13,INPUT!$A$2:$E$99998,5,FALSE),0) -> 69 | F13: =IFERROR(VLOOKUP(C13,INPUT!$H$2:$N2410,7,FALSE),"")
A14: 9 | B14: =IFERROR(VLOOKUP(C14,INPUT!$A$2:$E$99998,3,FALSE),"") -> Bulong Inox 304 M10x30 | C14: CX1NOA0009 | D14: =IFERROR(VLOOKUP(C14,INPUT!$A$2:$D$99998,4,FALSE),"") -> Cái | E14: =IFERROR(VLOOKUP(C14,INPUT!$A$2:$E$99998,5,FALSE),0) -> 147 | F14: =IFERROR(VLOOKUP(C14,INPUT!$H$2:$N2410,7,FALSE),"")
A15: 10 | B15: =IFERROR(VLOOKUP(C15,INPUT!$A$2:$E$99998,3,FALSE),"") -> Bulong Inox 304 M12x30 | C15: CX1NOA0010 | D15: =IFERROR(VLOOKUP(C15,INPUT!$A$2:$D$99998,4,FALSE),"") -> Cái | E15: =IFERROR(VLOOKUP(C15,INPUT!$A$2:$E$99998,5,FALSE),0) -> 189 | F15: =IFERROR(VLOOKUP(C15,INPUT!$H$2:$N2410,7,FALSE),"")
A16: 11 | B16: =IFERROR(VLOOKUP(C16,INPUT!$A$2:$E$99998,3,FALSE),"") -> Bulong Inox 304 M12x40 | C16: CX1NOA0011 | D16: =IFERROR(VLOOKUP(C16,INPUT!$A$2:$D$99998,4,FALSE),"") -> Cái | E16: =IFERROR(VLOOKUP(C16,INPUT!$A$2:$E$99998,5,FALSE),0) -> 63 | F16: =IFERROR(VLOOKUP(C16,INPUT!$H$2:$N2410,7,FALSE),"")
A17: 12 | B17: =IFERROR(VLOOKUP(C17,INPUT!$A$2:$E$99998,3,FALSE),"") -> Bulong inox 304 M18x60 | C17: CX1NOA0012 | D17: =IFERROR(VLOOKUP(C17,INPUT!$A$2:$D$99998,4,FALSE),"") -> Cái | E17: =IFERROR(VLOOKUP(C17,INPUT!$A$2:$E$99998,5,FALSE),0) -> 77 | F17: =IFERROR(VLOOKUP(C17,INPUT!$H$2:$N2410,7,FALSE),"")
A18: 13 | B18: =IFERROR(VLOOKUP(C18,INPUT!$A$2:$E$99998,3,FALSE),"") -> Dây rút nhựa Tiến Phát 4*150mm | C18: CX1TPH0014 | D18: =IFERROR(VLOOKUP(C18,INPUT!$A$2:$D$99998,4,FALSE),"") -> bịch | E18: =IFERROR(VLOOKUP(C18,INPUT!$A$2:$E$99998,5,FALSE),0) -> 0 | F18: =IFERROR(VLOOKUP(C18,INPUT!$H$2:$N2410,7,FALSE),"")
A19: 14 | B19: =IFERROR(VLOOKUP(C19,INPUT!$A$2:$E$99998,3,FALSE),"") -> Dây rút nhựa Tiến Phát 5*250mm | C19: CX1TPH0015 | D19: =IFERROR(VLOOKUP(C19,INPUT!$A$2:$D$99998,4,FALSE),"") -> bịch | E19: =IFERROR(VLOOKUP(C19,INPUT!$A$2:$E$99998,5,FALSE),0) -> 0 | F19: =IFERROR(VLOOKUP(C19,INPUT!$H$2:$N2410,7,FALSE),"")
A20: 15 | B20: =IFERROR(VLOOKUP(C20,INPUT!$A$2:$E$99998,3,FALSE),"") -> Keo Loctite 567 250ml | C20: CX1LOC0016 | D20: =IFERROR(VLOOKUP(C20,INPUT!$A$2:$D$99998,4,FALSE),"") -> Chai | E20: =IFERROR(VLOOKUP(C20,INPUT!$A$2:$E$99998,5,FALSE),0) -> 7.5 | F20: =IFERROR(VLOOKUP(C20,INPUT!$H$2:$N2410,7,FALSE),"")
A21: 16 | B21: =IFERROR(VLOOKUP(C21,INPUT!$A$2:$E$99998,3,FALSE),"") -> Khí CO2 (CO2 Air) | C21: CX3NOA0017 | D21: =IFERROR(VLOOKUP(C21,INPUT!$A$2:$D$99998,4,FALSE),"") -> Chai | E21: =IFERROR(VLOOKUP(C21,INPUT!$A$2:$E$99998,5,FALSE),0) -> 0 | F21: =IFERROR(VLOOKUP(C21,INPUT!$H$2:$N2410,7,FALSE),"")
A22: 17 | B22: =IFERROR(VLOOKUP(C22,INPUT!$A$2:$E$99998,3,FALSE),"") -> Khớp xoay thẳng 2 inch inox 304 | C22: CX1GOL0018 | D22: =IFERROR(VLOOKUP(C22,INPUT!$A$2:$D$99998,4,FALSE),"") -> Cái | E22: =IFERROR(VLOOKUP(C22,INPUT!$A$2:$E$99998,5,FALSE),0) -> 0 | F22: =IFERROR(VLOOKUP(C22,INPUT!$H$2:$N2410,7,FALSE),"")
A23: 18 | B23: =IFERROR(VLOOKUP(C23,INPUT!$A$2:$E$99998,3,FALSE),"") -> Chai test hàn màu trắng Developer số 4 Nabakem | C23: CX2NAB0019 | D23: =IFERROR(VLOOKUP(C23,INPUT!$A$2:$D$99998,4,FALSE),"") -> Chai | E23: =IFERROR(VLOOKUP(C23,INPUT!$A$2:$E$99998,5,FALSE),0) -> 1 | F23: =IFERROR(VLOOKUP(C23,INPUT!$H$2:$N2410,7,FALSE),"")
A24: 19 | B24: =IFERROR(VLOOKUP(C24,INPUT!$A$2:$E$99998,3,FALSE),"") -> Nắp bịt Inox 304 DN50 | C24: CX1NOA0020 | D24: =IFERROR(VLOOKUP(C24,INPUT!$A$2:$D$99998,4,FALSE),"") -> Cái | E24: =IFERROR(VLOOKUP(C24,INPUT!$A$2:$E$99998,5,FALSE),0) -> 10 | F24: =IFERROR(VLOOKUP(C24,INPUT!$H$2:$N2410,7,FALSE),"")
A25: 20 | B25: =IFERROR(VLOOKUP(C25,INPUT!$A$2:$E$99998,3,FALSE),"") -> Nhôm hộp 50x50x5.0 Mờ, Xi Anode | C25: CX1NOA0021 | D25: =IFERROR(VLOOKUP(C25,INPUT!$A$2:$D$99998,4,FALSE),"") -> mm | E25: =IFERROR(VLOOKUP(C25,INPUT!$A$2:$E$99998,5,FALSE),0) -> 0 | F25: =IFERROR(VLOOKUP(C25,INPUT!$H$2:$N2410,7,FALSE),"")
A26: 21 | B26: =IFERROR(VLOOKUP(C26,INPUT!$A$2:$E$99998,3,FALSE),"") -> Ống inox 304 60x4.0mm | C26: CX1NOA0022 | D26: =IFERROR(VLOOKUP(C26,INPUT!$A$2:$D$99998,4,FALSE),"") -> mm | E26: =IFERROR(VLOOKUP(C26,INPUT!$A$2:$E$99998,5,FALSE),0) -> 5130 | F26: =IFERROR(VLOOKUP(C26,INPUT!$H$2:$N2410,7,FALSE),"")
A27: 22 | B27: =IFERROR(VLOOKUP(C27,INPUT!$A$2:$E$99998,3,FALSE),"") -> Que hàn Inox 308L 1.6x1000mm, hiệu MENAM | C27: CX1MNA0023 | D27: =IFERROR(VLOOKUP(C27,INPUT!$A$2:$D$99998,4,FALSE),"") -> kg | E27: =IFERROR(VLOOKUP(C27,INPUT!$A$2:$E$99998,5,FALSE),0) -> 0 | F27: =IFERROR(VLOOKUP(C27,INPUT!$H$2:$N2410,7,FALSE),"") -> 0
A28: 23 | B28: =IFERROR(VLOOKUP(C28,INPUT!$A$2:$E$99998,3,FALSE),"") -> Xích (Sên) tải HSB 428-132L Recto (XX Malaysia) | C28: CX1REC0024 | D28: =IFERROR(VLOOKUP(C28,INPUT!$A$2:$D$99998,4,FALSE),"") -> Cái | E28: =IFERROR(VLOOKUP(C28,INPUT!$A$2:$E$99998,5,FALSE),0) -> 2 | F28: =IFERROR(VLOOKUP(C28,INPUT!$H$2:$N2410,7,FALSE),"")
A29: 24 | B29: =IFERROR(VLOOKUP(C29,INPUT!$A$2:$E$99998,3,FALSE),"") -> Tán inox 304 M12 | C29: CX1NOA0025 | D29: =IFERROR(VLOOKUP(C29,INPUT!$A$2:$D$99998,4,FALSE),"") -> Cái | E29: =IFERROR(VLOOKUP(C29,INPUT!$A$2:$E$99998,5,FALSE),0) -> 972 | F29: =IFERROR(VLOOKUP(C29,INPUT!$H$2:$N2410,7,FALSE),"")
A30: 25 | B30: =IFERROR(VLOOKUP(C30,INPUT!$A$2:$E$99998,3,FALSE),"") -> Tán Inox 304 M18 | C30: CX1NOA0026 | D30: =IFERROR(VLOOKUP(C30,INPUT!$A$2:$D$99998,4,FALSE),"") -> Cái | E30: =IFERROR(VLOOKUP(C30,INPUT!$A$2:$E$99998,5,FALSE),0) -> 40 | F30: =IFERROR(VLOOKUP(C30,INPUT!$H$2:$N2410,7,FALSE),"")
A31: 26 | B31: =IFERROR(VLOOKUP(C31,INPUT!$A$2:$E$99998,3,FALSE),"") -> Tán thép đen M10 đầu 17 | C31: CX1NOA0027 | D31: =IFERROR(VLOOKUP(C31,INPUT!$A$2:$D$99998,4,FALSE),"") -> Con | E31: =IFERROR(VLOOKUP(C31,INPUT!$A$2:$E$99998,5,FALSE),0) -> 15 | F31: =IFERROR(VLOOKUP(C31,INPUT!$H$2:$N2410,7,FALSE),"")
A32: 27 | B32: =IFERROR(VLOOKUP(C32,INPUT!$A$2:$E$99998,3,FALSE),"") -> Thuốc tẩy mối hàn (Dung dịch tẩy inox 1lit/bình) | C32: CX2NOA0028 | D32: =IFERROR(VLOOKUP(C32,INPUT!$A$2:$D$99998,4,FALSE),"") -> Bình | E32: =IFERROR(VLOOKUP(C32,INPUT!$A$2:$E$99998,5,FALSE),0) -> 4 | F32: =IFERROR(VLOOKUP(C32,INPUT!$H$2:$N2410,7,FALSE),"")
A33: 28 | B33: =IFERROR(VLOOKUP(C33,INPUT!$A$2:$E$99998,3,FALSE),"") -> Gối đỡ BẠC ĐẠN (Ball Bearing) UCP212 CUXB | C33: CX1CUX0029 | D33: =IFERROR(VLOOKUP(C33,INPUT!$A$2:$D$99998,4,FALSE),"") -> Cái | E33: =IFERROR(VLOOKUP(C33,INPUT!$A$2:$E$99998,5,FALSE),0) -> 20 | F33: =IFERROR(VLOOKUP(C33,INPUT!$H$2:$N2410,7,FALSE),"")
A34: 29 | B34: =IFERROR(VLOOKUP(C34,INPUT!$A$2:$E$99998,3,FALSE),"") -> Bulong inox 304 M18x40 | C34: CX1NOA0030 | D34: =IFERROR(VLOOKUP(C34,INPUT!$A$2:$D$99998,4,FALSE),"") -> Cái | E34: =IFERROR(VLOOKUP(C34,INPUT!$A$2:$E$99998,5,FALSE),0) -> 1 | F34: =IFERROR(VLOOKUP(C34,INPUT!$H$2:$N2410,7,FALSE),"")
A35: 30 | B35: =IFERROR(VLOOKUP(C35,INPUT!$A$2:$E$99998,3,FALSE),"") -> Đá cắt Cn 100.1,5.16 | C35: CX1NOA0031 | D35: =IFERROR(VLOOKUP(C35,INPUT!$A$2:$D$99998,4,FALSE),"") -> Viên | E35: =IFERROR(VLOOKUP(C35,INPUT!$A$2:$E$99998,5,FALSE),0) -> 15 | F35: =IFERROR(VLOOKUP(C35,INPUT!$H$2:$N2410,7,FALSE),"")
A36: 31 | B36: =IFERROR(VLOOKUP(C36,INPUT!$A$2:$E$99998,3,FALSE),"") -> Đá mài HẢI DƯƠNG Bavia Cn 100.6.16 | C36: CX1HDU0032 | D36: =IFERROR(VLOOKUP(C36,INPUT!$A$2:$D$99998,4,FALSE),"") -> Viên | E36: =IFERROR(VLOOKUP(C36,INPUT!$A$2:$E$99998,5,FALSE),0) -> 20 | F36: =IFERROR(VLOOKUP(C36,INPUT!$H$2:$N2410,7,FALSE),"")
A37: 32 | B37: =IFERROR(VLOOKUP(C37,INPUT!$A$2:$E$99998,3,FALSE),"") -> Phụ kiện máy hàn mig: Đầu béc hàn mig 1.2mm x L45mm | C37: CX1NOA0033 | D37: =IFERROR(VLOOKUP(C37,INPUT!$A$2:$D$99998,4,FALSE),"") -> Cái | E37: =IFERROR(VLOOKUP(C37,INPUT!$A$2:$E$99998,5,FALSE),0) -> 10 | F37: =IFERROR(VLOOKUP(C37,INPUT!$H$2:$N2410,7,FALSE),"")
A38: 33 | B38: =IFERROR(VLOOKUP(C38,INPUT!$A$2:$E$99998,3,FALSE),"") -> Đầu giữ kẹp kim hàn 10N32 Black Wolf | C38: CX1BLA0034 | D38: =IFERROR(VLOOKUP(C38,INPUT!$A$2:$D$99998,4,FALSE),"") -> Cái | E38: =IFERROR(VLOOKUP(C38,INPUT!$A$2:$E$99998,5,FALSE),0) -> 9 | F38: =IFERROR(VLOOKUP(C38,INPUT!$H$2:$N2410,7,FALSE),"")
A39: 34 | B39: =IFERROR(VLOOKUP(C39,INPUT!$A$2:$E$99998,3,FALSE),"") -> Đầu giữ kẹp kim hàn 10N28 Black Wolf | C39: CX1BLA0035 | D39: =IFERROR(VLOOKUP(C39,INPUT!$A$2:$D$99998,4,FALSE),"") -> Cái | E39: =IFERROR(VLOOKUP(C39,INPUT!$A$2:$E$99998,5,FALSE),0) -> 10 | F39: =IFERROR(VLOOKUP(C39,INPUT!$H$2:$N2410,7,FALSE),"")
A40: 35 | B40: =IFERROR(VLOOKUP(C40,INPUT!$A$2:$E$99998,3,FALSE),"") -> Dây hàn K-81T-1.2 | C40: CX1NOA0036 | D40: =IFERROR(VLOOKUP(C40,INPUT!$A$2:$D$99998,4,FALSE),"") -> kg | E40: =IFERROR(VLOOKUP(C40,INPUT!$A$2:$E$99998,5,FALSE),0) -> 15 | F40: =IFERROR(VLOOKUP(C40,INPUT!$H$2:$N2410,7,FALSE),"")
A41: 36 | B41: =IFERROR(VLOOKUP(C41,INPUT!$A$2:$E$99998,3,FALSE),"") -> Que hàn nhôm CHG-AL5356 Phi 2.4 | C41: CX1NOA0037 | D41: =IFERROR(VLOOKUP(C41,INPUT!$A$2:$D$99998,4,FALSE),"") -> Cái | E41: =IFERROR(VLOOKUP(C41,INPUT!$A$2:$E$99998,5,FALSE),0) -> 507 | F41: =IFERROR(VLOOKUP(C41,INPUT!$H$2:$N2410,7,FALSE),"") -> 0
A42: 37 | B42: =IFERROR(VLOOKUP(C42,INPUT!$A$2:$E$99998,3,FALSE),"") -> Điện cực hàn vonfram WP20 2.4mm | C42: CX1VON0038 | D42: =IFERROR(VLOOKUP(C42,INPUT!$A$2:$D$99998,4,FALSE),"") -> Cái | E42: =IFERROR(VLOOKUP(C42,INPUT!$A$2:$E$99998,5,FALSE),0) -> 30 | F42: =IFERROR(VLOOKUP(C42,INPUT!$H$2:$N2410,7,FALSE),"")
A43: 38 | B43: =IFERROR(VLOOKUP(C43,INPUT!$A$2:$E$99998,3,FALSE),"") -> Điện cực hàn vonfram WP20 3.2mm | C43: CX1VON0039 | D43: =IFERROR(VLOOKUP(C43,INPUT!$A$2:$D$99998,4,FALSE),"") -> Cái | E43: =IFERROR(VLOOKUP(C43,INPUT!$A$2:$E$99998,5,FALSE),0) -> 9 | F43: =IFERROR(VLOOKUP(C43,INPUT!$H$2:$N2410,7,FALSE),"")
...

Sheet Đơn vị chính
A1: SỔ CHI TIẾT VẬT TƯ HÀNG HÓA
A2: Kho: Kho Nguyên vật liệu, Từ ngày 29/05/2026 đến ngày 31/10/2026
A4: Mã kho | B4: Tên kho | C4: Mã hàng | D4: Tên hàng | E4: Mô tả | F4: Ngày hạch toán | G4: Ngày chứng từ | H4: Số chứng từ | I4: Diễn giải | J4: ĐVT | K4: ĐVT chính (ĐVC) | L4: Đơn giá | M4: Nhập | O4: Xuất | Q4: Tồn | S4: TK Kho | T4: TK đối ứng | U4: Mã đối tượng THCP | V4: Tên đối tượng THCP | W4: Mã khoản mục CP | X4: Tên khoản mục CP
M5: Số lượng | N5: Giá trị | O5: Số lượng | P5: Giá trị | Q5: Số lượng | R5: Giá trị
A6: C | B6: Kho Nguyên vật liệu | C6: CX1AIR0319 | D6: Van AIRTAC M5PP210-08 | I6: Số dư đầu kỳ | J6: Cái | K6: Cái | L6: 250000 | M6: 0 | N6: 0 | O6: 0 | P6: 0 | Q6: 11 | R6: 2750000
A7: C | B7: Kho Nguyên vật liệu | C7: CX1ATL0390 | D7: Que hàn nhôm TIG CHG-AL3536 phi 1.6mm, hiệu ATLANTIC | I7: Số dư đầu kỳ | J7: que | K7: que | L7: 946.97 | M7: 0 | N7: 0 | O7: 0 | P7: 0 | Q7: 381 | R7: 360795
A8: C | B8: Kho Nguyên vật liệu | C8: CX1ATL0395 | D8: Que hàn Inox CHG-308 phi 1.6mm, hiệu ATLANTIC | I8: Số dư đầu kỳ | J8: kg | K8: kg | L8: 172727.2 | M8: 0 | N8: 0 | O8: 0 | P8: 0 | Q8: 5 | R8: 863636
A9: C | B9: Kho Nguyên vật liệu | C9: CX1ATL0395 | D9: Que hàn Inox CHG-308 phi 1.6mm, hiệu ATLANTIC | F9: 46223 | G9: 46223 | H9: XK26/175 | I9: Vật liệu tiêu hao | J9: kg | K9: kg | L9: 172727.2 | M9: 0 | N9: 0 | O9: 0.24 | P9: 41455 | Q9: 4.76 | R9: 822181 | S9: 152 | T9: 154 | W9: SXC.VL | X9: Chi phí vật liệu
A10: C | B10: Kho Nguyên vật liệu | C10: CX1ATL0395 | D10: Que hàn Inox CHG-308 phi 1.6mm, hiệu ATLANTIC | F10: 46233 | G10: 46233 | H10: XK26/202 | I10: Xuất kho sản xuất | J10: kg | K10: kg | L10: 172727.2 | M10: 0 | N10: 0 | O10: 0.31 | P10: 53545 | Q10: 4.45 | R10: 768636 | S10: 152 | T10: 154 | U10: DX1TNJ0024 | V10: Rulo cuốn ống đơn cấp bằng nhôm 2 inch 60 feet. Model: HRS20A6003. Hiệu: TECHNOJET | W10: SXC.VL | X10: Chi phí vật liệu
A11: C | B11: Kho Nguyên vật liệu | C11: CX1ATL0395 | D11: Que hàn Inox CHG-308 phi 1.6mm, hiệu ATLANTIC | F11: 46238 | G11: 46238 | H11: XK26/206 | I11: Xuất kho sản xuất | J11: kg | K11: kg | L11: 172727.19 | M11: 0 | N11: 0 | O11: 0.15 | P11: 25909 | Q11: 4.3 | R11: 742727 | S11: 152 | T11: 154 | U11: DX1TNJ0024 | V11: Rulo cuốn ống đơn cấp bằng nhôm 2 inch 60 feet. Model: HRS20A6003. Hiệu: TECHNOJET | W11: SXC.VL | X11: Chi phí vật liệu
A12: C | B12: Kho Nguyên vật liệu | C12: CX1ATL0395 | D12: Que hàn Inox CHG-308 phi 1.6mm, hiệu ATLANTIC | F12: 46239 | G12: 46239 | H12: XK26/209 | I12: Xuất kho sản xuất | J12: kg | K12: kg | L12: 172727.19 | M12: 0 | N12: 0 | O12: 0.08 | P12: 13818 | Q12: 4.22 | R12: 728909 | S12: 152 | T12: 154 | U12: DX1TNJ0024 | V12: Rulo cuốn ống đơn cấp bằng nhôm 2 inch 60 feet. Model: HRS20A6003. Hiệu: TECHNOJET | W12: SXC.VL | X12: Chi phí vật liệu
A13: C | B13: Kho Nguyên vật liệu | C13: CX1ATL0395 | D13: Que hàn Inox CHG-308 phi 1.6mm, hiệu ATLANTIC | F13: 46240 | G13: 46240 | H13: XK26/217 | I13: Xuất kho sản xuất | J13: kg | K13: kg | L13: 172727.19 | M13: 0 | N13: 0 | O13: 0.46 | P13: 79455 | Q13: 3.76 | R13: 649454 | S13: 152 | T13: 154 | U13: DX1TNJ0023 | V13: Rulo cuốn ống đa cấp bằng nhôm 3 inch 60 feet. Model: HRM30A6001. Hiệu: TECHNOJET | W13: SXC.VL | X13: Chi phí vật liệu
A14: C | B14: Kho Nguyên vật liệu | C14: CX1ATL0395 | D14: Que hàn Inox CHG-308 phi 1.6mm, hiệu ATLANTIC | F14: 46246 | G14: 46246 | H14: XK26/219 | I14: Xuất kho sản xuất | J14: kg | K14: kg | L14: 172727.19 | M14: 0 | N14: 0 | O14: 0.15 | P14: 25909 | Q14: 3.61 | R14: 623545 | S14: 152 | T14: 154 | U14: DX1TNJ0023 | V14: Rulo cuốn ống đa cấp bằng nhôm 3 inch 60 feet. Model: HRM30A6001. Hiệu: TECHNOJET | W14: SXC.VL | X14: Chi phí vật liệu
A15: C | B15: Kho Nguyên vật liệu | C15: CX1ATL0395 | D15: Que hàn Inox CHG-308 phi 1.6mm, hiệu ATLANTIC | F15: 46248 | G15: 46248 | H15: XK26/226 | I15: Xuất kho sản xuất | J15: kg | K15: kg | L15: 172727.19 | M15: 0 | N15: 0 | O15: 0.15 | P15: 25909 | Q15: 3.46 | R15: 597636 | S15: 152 | T15: 154 | U15: DX1TNJ0023 | V15: Rulo cuốn ống đa cấp bằng nhôm 3 inch 60 feet. Model: HRM30A6001. Hiệu: TECHNOJET | W15: SXC.VL | X15: Chi phí vật liệu
A16: C | B16: Kho Nguyên vật liệu | C16: CX1ATL0395 | D16: Que hàn Inox CHG-308 phi 1.6mm, hiệu ATLANTIC | F16: 46260 | G16: 46260 | H16: XK26/253 | I16: Xuất kho sản xuất | J16: kg | K16: kg | L16: 172727.19 | M16: 0 | N16: 0 | O16: 0.15 | P16: 25909 | Q16: 3.31 | R16: 571727 | S16: 152 | T16: 154 | U16: DX1TNJ0023 | V16: Rulo cuốn ống đa cấp bằng nhôm 3 inch 60 feet. Model: HRM30A6001. Hiệu: TECHNOJET | W16: SXC.VL | X16: Chi phí vật liệu
A17: C | B17: Kho Nguyên vật liệu | C17: CX1ATL0395 | D17: Que hàn Inox CHG-308 phi 1.6mm, hiệu ATLANTIC | F17: 46293 | G17: 46293 | H17: XK26/334 | I17: Xuất kho sản xuất | J17: kg | K17: kg | L17: 172727.19 | M17: 0 | N17: 0 | O17: 0.46 | P17: 79455 | Q17: 2.85 | R17: 492272 | S17: 152 | T17: 154 | U17: DX1TNJ0023 | V17: Rulo cuốn ống đa cấp bằng nhôm 3 inch 60 feet. Model: HRM30A6001. Hiệu: TECHNOJET | W17: SXC.VL | X17: Chi phí vật liệu
A18: C | B18: Kho Nguyên vật liệu | C18: CX1ATL0395 | D18: Que hàn Inox CHG-308 phi 1.6mm, hiệu ATLANTIC | F18: 46297 | G18: 46297 | H18: XK26/342 | I18: Xuất kho sản xuất | J18: kg | K18: kg | L18: 172727.02 | M18: 0 | N18: 0 | O18: 0.31 | P18: 53545 | Q18: 2.54 | R18: 438727 | S18: 152 | T18: 154 | U18: DX1TNJ0024 | V18: Rulo cuốn ống đơn cấp bằng nhôm 2 inch 60 feet. Model: HRS20A6003. Hiệu: TECHNOJET | W18: SXC.VL | X18: Chi phí vật liệu
